[2024-10-29 14:50:18,132] {taskinstance.py:1159} INFO - Dependencies all met for <TaskInstance: dados_climaticos.extrai_dados scheduled__2024-10-07T00:00:00+00:00 [queued]>
[2024-10-29 14:50:18,136] {taskinstance.py:1159} INFO - Dependencies all met for <TaskInstance: dados_climaticos.extrai_dados scheduled__2024-10-07T00:00:00+00:00 [queued]>
[2024-10-29 14:50:18,137] {taskinstance.py:1356} INFO - 
--------------------------------------------------------------------------------
[2024-10-29 14:50:18,137] {taskinstance.py:1357} INFO - Starting attempt 1 of 1
[2024-10-29 14:50:18,137] {taskinstance.py:1358} INFO - 
--------------------------------------------------------------------------------
[2024-10-29 14:50:18,148] {taskinstance.py:1377} INFO - Executing <Task(PythonOperator): extrai_dados> on 2024-10-07 00:00:00+00:00
[2024-10-29 14:50:18,151] {standard_task_runner.py:52} INFO - Started process 111042 to run task
[2024-10-29 14:50:18,153] {standard_task_runner.py:79} INFO - Running: ['airflow', 'tasks', 'run', 'dados_climaticos', 'extrai_dados', 'scheduled__2024-10-07T00:00:00+00:00', '--job-id', '40', '--raw', '--subdir', 'DAGS_FOLDER/dados_climaticos.py', '--cfg-path', '/tmp/tmp7y8m63p5', '--error-file', '/tmp/tmpygve6_uw']
[2024-10-29 14:50:18,153] {standard_task_runner.py:80} INFO - Job 40: Subtask extrai_dados
[2024-10-29 14:50:18,177] {task_command.py:370} INFO - Running <TaskInstance: dados_climaticos.extrai_dados scheduled__2024-10-07T00:00:00+00:00 [running]> on host LAPTOP-SNAE0A1O.
[2024-10-29 14:50:18,195] {taskinstance.py:1889} ERROR - Task failed with exception
Traceback (most recent call last):
  File "/root/Documentos/airflow/venv/lib/python3.9/site-packages/airflow/models/taskinstance.py", line 1451, in _run_raw_task
    self._execute_task_with_callbacks(context, test_mode)
  File "/root/Documentos/airflow/venv/lib/python3.9/site-packages/airflow/models/taskinstance.py", line 1555, in _execute_task_with_callbacks
    task_orig = self.render_templates(context=context)
  File "/root/Documentos/airflow/venv/lib/python3.9/site-packages/airflow/models/taskinstance.py", line 2212, in render_templates
    rendered_task = self.task.render_template_fields(context)
  File "/root/Documentos/airflow/venv/lib/python3.9/site-packages/airflow/models/baseoperator.py", line 1185, in render_template_fields
    self._do_render_template_fields(self, self.template_fields, context, jinja_env, set())
  File "/root/Documentos/airflow/venv/lib/python3.9/site-packages/airflow/utils/session.py", line 71, in wrapper
    return func(*args, session=session, **kwargs)
  File "/root/Documentos/airflow/venv/lib/python3.9/site-packages/airflow/models/abstractoperator.py", line 344, in _do_render_template_fields
    rendered_content = self.render_template(
  File "/root/Documentos/airflow/venv/lib/python3.9/site-packages/airflow/models/abstractoperator.py", line 404, in render_template
    return {key: self.render_template(value, context, jinja_env) for key, value in value.items()}
  File "/root/Documentos/airflow/venv/lib/python3.9/site-packages/airflow/models/abstractoperator.py", line 404, in <dictcomp>
    return {key: self.render_template(value, context, jinja_env) for key, value in value.items()}
  File "/root/Documentos/airflow/venv/lib/python3.9/site-packages/airflow/models/abstractoperator.py", line 387, in render_template
    template = jinja_env.from_string(value)
  File "/root/Documentos/airflow/venv/lib/python3.9/site-packages/jinja2/environment.py", line 1092, in from_string
    return cls.from_code(self, self.compile(source), gs, None)
  File "/root/Documentos/airflow/venv/lib/python3.9/site-packages/jinja2/environment.py", line 757, in compile
    self.handle_exception(source=source_hint)
  File "/root/Documentos/airflow/venv/lib/python3.9/site-packages/jinja2/environment.py", line 925, in handle_exception
    raise rewrite_traceback_stack(source=source)
  File "<unknown>", line 1, in template
jinja2.exceptions.TemplateSyntaxError: unexpected char '"' at 29
[2024-10-29 14:50:18,197] {taskinstance.py:1395} INFO - Marking task as FAILED. dag_id=dados_climaticos, task_id=extrai_dados, execution_date=20241007T000000, start_date=20241029T175018, end_date=20241029T175018
[2024-10-29 14:50:18,208] {standard_task_runner.py:92} ERROR - Failed to execute job 40 for task extrai_dados (unexpected char '"' at 29; 111042)
[2024-10-29 14:50:18,246] {local_task_job.py:156} INFO - Task exited with return code 1
[2024-10-29 14:50:18,256] {local_task_job.py:273} INFO - 0 downstream tasks scheduled from follow-on schedule check
[2024-10-29 14:53:45,608] {taskinstance.py:1159} INFO - Dependencies all met for <TaskInstance: dados_climaticos.extrai_dados scheduled__2024-10-07T00:00:00+00:00 [queued]>
[2024-10-29 14:53:45,612] {taskinstance.py:1159} INFO - Dependencies all met for <TaskInstance: dados_climaticos.extrai_dados scheduled__2024-10-07T00:00:00+00:00 [queued]>
[2024-10-29 14:53:45,613] {taskinstance.py:1356} INFO - 
--------------------------------------------------------------------------------
[2024-10-29 14:53:45,613] {taskinstance.py:1357} INFO - Starting attempt 1 of 1
[2024-10-29 14:53:45,613] {taskinstance.py:1358} INFO - 
--------------------------------------------------------------------------------
[2024-10-29 14:53:45,624] {taskinstance.py:1377} INFO - Executing <Task(PythonOperator): extrai_dados> on 2024-10-07 00:00:00+00:00
[2024-10-29 14:53:45,627] {standard_task_runner.py:52} INFO - Started process 112770 to run task
[2024-10-29 14:53:45,629] {standard_task_runner.py:79} INFO - Running: ['airflow', 'tasks', 'run', 'dados_climaticos', 'extrai_dados', 'scheduled__2024-10-07T00:00:00+00:00', '--job-id', '40', '--raw', '--subdir', 'DAGS_FOLDER/dados_climaticos.py', '--cfg-path', '/tmp/tmptfni5uw5', '--error-file', '/tmp/tmpf9ad5ou_']
[2024-10-29 14:53:45,629] {standard_task_runner.py:80} INFO - Job 40: Subtask extrai_dados
[2024-10-29 14:53:45,654] {task_command.py:370} INFO - Running <TaskInstance: dados_climaticos.extrai_dados scheduled__2024-10-07T00:00:00+00:00 [running]> on host LAPTOP-SNAE0A1O.
[2024-10-29 14:53:45,671] {taskinstance.py:1889} ERROR - Task failed with exception
Traceback (most recent call last):
  File "/root/Documentos/airflow/venv/lib/python3.9/site-packages/airflow/models/taskinstance.py", line 1451, in _run_raw_task
    self._execute_task_with_callbacks(context, test_mode)
  File "/root/Documentos/airflow/venv/lib/python3.9/site-packages/airflow/models/taskinstance.py", line 1555, in _execute_task_with_callbacks
    task_orig = self.render_templates(context=context)
  File "/root/Documentos/airflow/venv/lib/python3.9/site-packages/airflow/models/taskinstance.py", line 2212, in render_templates
    rendered_task = self.task.render_template_fields(context)
  File "/root/Documentos/airflow/venv/lib/python3.9/site-packages/airflow/models/baseoperator.py", line 1185, in render_template_fields
    self._do_render_template_fields(self, self.template_fields, context, jinja_env, set())
  File "/root/Documentos/airflow/venv/lib/python3.9/site-packages/airflow/utils/session.py", line 71, in wrapper
    return func(*args, session=session, **kwargs)
  File "/root/Documentos/airflow/venv/lib/python3.9/site-packages/airflow/models/abstractoperator.py", line 344, in _do_render_template_fields
    rendered_content = self.render_template(
  File "/root/Documentos/airflow/venv/lib/python3.9/site-packages/airflow/models/abstractoperator.py", line 404, in render_template
    return {key: self.render_template(value, context, jinja_env) for key, value in value.items()}
  File "/root/Documentos/airflow/venv/lib/python3.9/site-packages/airflow/models/abstractoperator.py", line 404, in <dictcomp>
    return {key: self.render_template(value, context, jinja_env) for key, value in value.items()}
  File "/root/Documentos/airflow/venv/lib/python3.9/site-packages/airflow/models/abstractoperator.py", line 387, in render_template
    template = jinja_env.from_string(value)
  File "/root/Documentos/airflow/venv/lib/python3.9/site-packages/jinja2/environment.py", line 1092, in from_string
    return cls.from_code(self, self.compile(source), gs, None)
  File "/root/Documentos/airflow/venv/lib/python3.9/site-packages/jinja2/environment.py", line 757, in compile
    self.handle_exception(source=source_hint)
  File "/root/Documentos/airflow/venv/lib/python3.9/site-packages/jinja2/environment.py", line 925, in handle_exception
    raise rewrite_traceback_stack(source=source)
  File "<unknown>", line 1, in template
jinja2.exceptions.TemplateSyntaxError: unexpected char '"' at 29
[2024-10-29 14:53:45,674] {taskinstance.py:1395} INFO - Marking task as FAILED. dag_id=dados_climaticos, task_id=extrai_dados, execution_date=20241007T000000, start_date=20241029T175345, end_date=20241029T175345
[2024-10-29 14:53:45,684] {standard_task_runner.py:92} ERROR - Failed to execute job 40 for task extrai_dados (unexpected char '"' at 29; 112770)
[2024-10-29 14:53:45,721] {local_task_job.py:156} INFO - Task exited with return code 1
[2024-10-29 14:53:45,732] {local_task_job.py:273} INFO - 0 downstream tasks scheduled from follow-on schedule check
[2024-10-29 14:56:51,482] {taskinstance.py:1159} INFO - Dependencies all met for <TaskInstance: dados_climaticos.extrai_dados scheduled__2024-10-07T00:00:00+00:00 [queued]>
[2024-10-29 14:56:51,487] {taskinstance.py:1159} INFO - Dependencies all met for <TaskInstance: dados_climaticos.extrai_dados scheduled__2024-10-07T00:00:00+00:00 [queued]>
[2024-10-29 14:56:51,487] {taskinstance.py:1356} INFO - 
--------------------------------------------------------------------------------
[2024-10-29 14:56:51,487] {taskinstance.py:1357} INFO - Starting attempt 1 of 1
[2024-10-29 14:56:51,487] {taskinstance.py:1358} INFO - 
--------------------------------------------------------------------------------
[2024-10-29 14:56:51,501] {taskinstance.py:1377} INFO - Executing <Task(PythonOperator): extrai_dados> on 2024-10-07 00:00:00+00:00
[2024-10-29 14:56:51,504] {standard_task_runner.py:52} INFO - Started process 114307 to run task
[2024-10-29 14:56:51,506] {standard_task_runner.py:79} INFO - Running: ['airflow', 'tasks', 'run', 'dados_climaticos', 'extrai_dados', 'scheduled__2024-10-07T00:00:00+00:00', '--job-id', '40', '--raw', '--subdir', 'DAGS_FOLDER/dados_climaticos.py', '--cfg-path', '/tmp/tmppmrv1w30', '--error-file', '/tmp/tmpc5_fjis5']
[2024-10-29 14:56:51,506] {standard_task_runner.py:80} INFO - Job 40: Subtask extrai_dados
[2024-10-29 14:56:51,530] {task_command.py:370} INFO - Running <TaskInstance: dados_climaticos.extrai_dados scheduled__2024-10-07T00:00:00+00:00 [running]> on host LAPTOP-SNAE0A1O.
[2024-10-29 14:56:51,547] {taskinstance.py:1889} ERROR - Task failed with exception
Traceback (most recent call last):
  File "/root/Documentos/airflow/venv/lib/python3.9/site-packages/airflow/models/taskinstance.py", line 1451, in _run_raw_task
    self._execute_task_with_callbacks(context, test_mode)
  File "/root/Documentos/airflow/venv/lib/python3.9/site-packages/airflow/models/taskinstance.py", line 1555, in _execute_task_with_callbacks
    task_orig = self.render_templates(context=context)
  File "/root/Documentos/airflow/venv/lib/python3.9/site-packages/airflow/models/taskinstance.py", line 2212, in render_templates
    rendered_task = self.task.render_template_fields(context)
  File "/root/Documentos/airflow/venv/lib/python3.9/site-packages/airflow/models/baseoperator.py", line 1185, in render_template_fields
    self._do_render_template_fields(self, self.template_fields, context, jinja_env, set())
  File "/root/Documentos/airflow/venv/lib/python3.9/site-packages/airflow/utils/session.py", line 71, in wrapper
    return func(*args, session=session, **kwargs)
  File "/root/Documentos/airflow/venv/lib/python3.9/site-packages/airflow/models/abstractoperator.py", line 344, in _do_render_template_fields
    rendered_content = self.render_template(
  File "/root/Documentos/airflow/venv/lib/python3.9/site-packages/airflow/models/abstractoperator.py", line 404, in render_template
    return {key: self.render_template(value, context, jinja_env) for key, value in value.items()}
  File "/root/Documentos/airflow/venv/lib/python3.9/site-packages/airflow/models/abstractoperator.py", line 404, in <dictcomp>
    return {key: self.render_template(value, context, jinja_env) for key, value in value.items()}
  File "/root/Documentos/airflow/venv/lib/python3.9/site-packages/airflow/models/abstractoperator.py", line 387, in render_template
    template = jinja_env.from_string(value)
  File "/root/Documentos/airflow/venv/lib/python3.9/site-packages/jinja2/environment.py", line 1092, in from_string
    return cls.from_code(self, self.compile(source), gs, None)
  File "/root/Documentos/airflow/venv/lib/python3.9/site-packages/jinja2/environment.py", line 757, in compile
    self.handle_exception(source=source_hint)
  File "/root/Documentos/airflow/venv/lib/python3.9/site-packages/jinja2/environment.py", line 925, in handle_exception
    raise rewrite_traceback_stack(source=source)
  File "<unknown>", line 1, in template
jinja2.exceptions.TemplateSyntaxError: unexpected char '"' at 29
[2024-10-29 14:56:51,550] {taskinstance.py:1395} INFO - Marking task as FAILED. dag_id=dados_climaticos, task_id=extrai_dados, execution_date=20241007T000000, start_date=20241029T175651, end_date=20241029T175651
[2024-10-29 14:56:51,560] {standard_task_runner.py:92} ERROR - Failed to execute job 40 for task extrai_dados (unexpected char '"' at 29; 114307)
[2024-10-29 14:56:51,598] {local_task_job.py:156} INFO - Task exited with return code 1
[2024-10-29 14:56:51,617] {local_task_job.py:273} INFO - 0 downstream tasks scheduled from follow-on schedule check
[2024-10-29 15:02:44,886] {taskinstance.py:1159} INFO - Dependencies all met for <TaskInstance: dados_climaticos.extrai_dados scheduled__2024-10-07T00:00:00+00:00 [queued]>
[2024-10-29 15:02:44,890] {taskinstance.py:1159} INFO - Dependencies all met for <TaskInstance: dados_climaticos.extrai_dados scheduled__2024-10-07T00:00:00+00:00 [queued]>
[2024-10-29 15:02:44,890] {taskinstance.py:1356} INFO - 
--------------------------------------------------------------------------------
[2024-10-29 15:02:44,890] {taskinstance.py:1357} INFO - Starting attempt 1 of 1
[2024-10-29 15:02:44,890] {taskinstance.py:1358} INFO - 
--------------------------------------------------------------------------------
[2024-10-29 15:02:44,902] {taskinstance.py:1377} INFO - Executing <Task(PythonOperator): extrai_dados> on 2024-10-07 00:00:00+00:00
[2024-10-29 15:02:44,904] {standard_task_runner.py:52} INFO - Started process 117133 to run task
[2024-10-29 15:02:44,906] {standard_task_runner.py:79} INFO - Running: ['airflow', 'tasks', 'run', 'dados_climaticos', 'extrai_dados', 'scheduled__2024-10-07T00:00:00+00:00', '--job-id', '40', '--raw', '--subdir', 'DAGS_FOLDER/dados_climaticos.py', '--cfg-path', '/tmp/tmpdlj5qkks', '--error-file', '/tmp/tmp4axx_5la']
[2024-10-29 15:02:44,907] {standard_task_runner.py:80} INFO - Job 40: Subtask extrai_dados
[2024-10-29 15:02:44,931] {task_command.py:370} INFO - Running <TaskInstance: dados_climaticos.extrai_dados scheduled__2024-10-07T00:00:00+00:00 [running]> on host LAPTOP-SNAE0A1O.
[2024-10-29 15:02:44,949] {taskinstance.py:1889} ERROR - Task failed with exception
Traceback (most recent call last):
  File "/root/Documentos/airflow/venv/lib/python3.9/site-packages/airflow/models/taskinstance.py", line 1451, in _run_raw_task
    self._execute_task_with_callbacks(context, test_mode)
  File "/root/Documentos/airflow/venv/lib/python3.9/site-packages/airflow/models/taskinstance.py", line 1555, in _execute_task_with_callbacks
    task_orig = self.render_templates(context=context)
  File "/root/Documentos/airflow/venv/lib/python3.9/site-packages/airflow/models/taskinstance.py", line 2212, in render_templates
    rendered_task = self.task.render_template_fields(context)
  File "/root/Documentos/airflow/venv/lib/python3.9/site-packages/airflow/models/baseoperator.py", line 1185, in render_template_fields
    self._do_render_template_fields(self, self.template_fields, context, jinja_env, set())
  File "/root/Documentos/airflow/venv/lib/python3.9/site-packages/airflow/utils/session.py", line 71, in wrapper
    return func(*args, session=session, **kwargs)
  File "/root/Documentos/airflow/venv/lib/python3.9/site-packages/airflow/models/abstractoperator.py", line 344, in _do_render_template_fields
    rendered_content = self.render_template(
  File "/root/Documentos/airflow/venv/lib/python3.9/site-packages/airflow/models/abstractoperator.py", line 404, in render_template
    return {key: self.render_template(value, context, jinja_env) for key, value in value.items()}
  File "/root/Documentos/airflow/venv/lib/python3.9/site-packages/airflow/models/abstractoperator.py", line 404, in <dictcomp>
    return {key: self.render_template(value, context, jinja_env) for key, value in value.items()}
  File "/root/Documentos/airflow/venv/lib/python3.9/site-packages/airflow/models/abstractoperator.py", line 387, in render_template
    template = jinja_env.from_string(value)
  File "/root/Documentos/airflow/venv/lib/python3.9/site-packages/jinja2/environment.py", line 1092, in from_string
    return cls.from_code(self, self.compile(source), gs, None)
  File "/root/Documentos/airflow/venv/lib/python3.9/site-packages/jinja2/environment.py", line 757, in compile
    self.handle_exception(source=source_hint)
  File "/root/Documentos/airflow/venv/lib/python3.9/site-packages/jinja2/environment.py", line 925, in handle_exception
    raise rewrite_traceback_stack(source=source)
  File "<unknown>", line 1, in template
jinja2.exceptions.TemplateSyntaxError: unexpected char '"' at 29
[2024-10-29 15:02:44,952] {taskinstance.py:1395} INFO - Marking task as FAILED. dag_id=dados_climaticos, task_id=extrai_dados, execution_date=20241007T000000, start_date=20241029T180244, end_date=20241029T180244
[2024-10-29 15:02:44,963] {standard_task_runner.py:92} ERROR - Failed to execute job 40 for task extrai_dados (unexpected char '"' at 29; 117133)
[2024-10-29 15:02:44,999] {local_task_job.py:156} INFO - Task exited with return code 1
[2024-10-29 15:02:45,009] {local_task_job.py:273} INFO - 0 downstream tasks scheduled from follow-on schedule check
[2024-10-29 15:05:39,048] {taskinstance.py:1159} INFO - Dependencies all met for <TaskInstance: dados_climaticos.extrai_dados scheduled__2024-10-07T00:00:00+00:00 [queued]>
[2024-10-29 15:05:39,053] {taskinstance.py:1159} INFO - Dependencies all met for <TaskInstance: dados_climaticos.extrai_dados scheduled__2024-10-07T00:00:00+00:00 [queued]>
[2024-10-29 15:05:39,053] {taskinstance.py:1356} INFO - 
--------------------------------------------------------------------------------
[2024-10-29 15:05:39,053] {taskinstance.py:1357} INFO - Starting attempt 1 of 1
[2024-10-29 15:05:39,054] {taskinstance.py:1358} INFO - 
--------------------------------------------------------------------------------
[2024-10-29 15:05:39,065] {taskinstance.py:1377} INFO - Executing <Task(PythonOperator): extrai_dados> on 2024-10-07 00:00:00+00:00
[2024-10-29 15:05:39,067] {standard_task_runner.py:52} INFO - Started process 118601 to run task
[2024-10-29 15:05:39,069] {standard_task_runner.py:79} INFO - Running: ['airflow', 'tasks', 'run', 'dados_climaticos', 'extrai_dados', 'scheduled__2024-10-07T00:00:00+00:00', '--job-id', '40', '--raw', '--subdir', 'DAGS_FOLDER/dados_climaticos.py', '--cfg-path', '/tmp/tmp3yuzzcnd', '--error-file', '/tmp/tmp24dgdfi2']
[2024-10-29 15:05:39,069] {standard_task_runner.py:80} INFO - Job 40: Subtask extrai_dados
[2024-10-29 15:05:39,093] {task_command.py:370} INFO - Running <TaskInstance: dados_climaticos.extrai_dados scheduled__2024-10-07T00:00:00+00:00 [running]> on host LAPTOP-SNAE0A1O.
[2024-10-29 15:05:39,110] {taskinstance.py:1889} ERROR - Task failed with exception
Traceback (most recent call last):
  File "/root/Documentos/airflow/venv/lib/python3.9/site-packages/airflow/models/taskinstance.py", line 1451, in _run_raw_task
    self._execute_task_with_callbacks(context, test_mode)
  File "/root/Documentos/airflow/venv/lib/python3.9/site-packages/airflow/models/taskinstance.py", line 1555, in _execute_task_with_callbacks
    task_orig = self.render_templates(context=context)
  File "/root/Documentos/airflow/venv/lib/python3.9/site-packages/airflow/models/taskinstance.py", line 2212, in render_templates
    rendered_task = self.task.render_template_fields(context)
  File "/root/Documentos/airflow/venv/lib/python3.9/site-packages/airflow/models/baseoperator.py", line 1185, in render_template_fields
    self._do_render_template_fields(self, self.template_fields, context, jinja_env, set())
  File "/root/Documentos/airflow/venv/lib/python3.9/site-packages/airflow/utils/session.py", line 71, in wrapper
    return func(*args, session=session, **kwargs)
  File "/root/Documentos/airflow/venv/lib/python3.9/site-packages/airflow/models/abstractoperator.py", line 344, in _do_render_template_fields
    rendered_content = self.render_template(
  File "/root/Documentos/airflow/venv/lib/python3.9/site-packages/airflow/models/abstractoperator.py", line 404, in render_template
    return {key: self.render_template(value, context, jinja_env) for key, value in value.items()}
  File "/root/Documentos/airflow/venv/lib/python3.9/site-packages/airflow/models/abstractoperator.py", line 404, in <dictcomp>
    return {key: self.render_template(value, context, jinja_env) for key, value in value.items()}
  File "/root/Documentos/airflow/venv/lib/python3.9/site-packages/airflow/models/abstractoperator.py", line 387, in render_template
    template = jinja_env.from_string(value)
  File "/root/Documentos/airflow/venv/lib/python3.9/site-packages/jinja2/environment.py", line 1092, in from_string
    return cls.from_code(self, self.compile(source), gs, None)
  File "/root/Documentos/airflow/venv/lib/python3.9/site-packages/jinja2/environment.py", line 757, in compile
    self.handle_exception(source=source_hint)
  File "/root/Documentos/airflow/venv/lib/python3.9/site-packages/jinja2/environment.py", line 925, in handle_exception
    raise rewrite_traceback_stack(source=source)
  File "<unknown>", line 1, in template
jinja2.exceptions.TemplateSyntaxError: unexpected char '"' at 29
[2024-10-29 15:05:39,113] {taskinstance.py:1395} INFO - Marking task as FAILED. dag_id=dados_climaticos, task_id=extrai_dados, execution_date=20241007T000000, start_date=20241029T180539, end_date=20241029T180539
[2024-10-29 15:05:39,123] {standard_task_runner.py:92} ERROR - Failed to execute job 40 for task extrai_dados (unexpected char '"' at 29; 118601)
[2024-10-29 15:05:39,161] {local_task_job.py:156} INFO - Task exited with return code 1
[2024-10-29 15:05:39,173] {local_task_job.py:273} INFO - 0 downstream tasks scheduled from follow-on schedule check
[2024-10-29 15:11:05,072] {taskinstance.py:1159} INFO - Dependencies all met for <TaskInstance: dados_climaticos.extrai_dados scheduled__2024-10-07T00:00:00+00:00 [queued]>
[2024-10-29 15:11:05,076] {taskinstance.py:1159} INFO - Dependencies all met for <TaskInstance: dados_climaticos.extrai_dados scheduled__2024-10-07T00:00:00+00:00 [queued]>
[2024-10-29 15:11:05,076] {taskinstance.py:1356} INFO - 
--------------------------------------------------------------------------------
[2024-10-29 15:11:05,076] {taskinstance.py:1357} INFO - Starting attempt 1 of 1
[2024-10-29 15:11:05,076] {taskinstance.py:1358} INFO - 
--------------------------------------------------------------------------------
[2024-10-29 15:11:05,087] {taskinstance.py:1377} INFO - Executing <Task(PythonOperator): extrai_dados> on 2024-10-07 00:00:00+00:00
[2024-10-29 15:11:05,090] {standard_task_runner.py:52} INFO - Started process 121227 to run task
[2024-10-29 15:11:05,092] {standard_task_runner.py:79} INFO - Running: ['airflow', 'tasks', 'run', 'dados_climaticos', 'extrai_dados', 'scheduled__2024-10-07T00:00:00+00:00', '--job-id', '40', '--raw', '--subdir', 'DAGS_FOLDER/dados_climaticos.py', '--cfg-path', '/tmp/tmpe2ohtq5x', '--error-file', '/tmp/tmpopsrhsng']
[2024-10-29 15:11:05,092] {standard_task_runner.py:80} INFO - Job 40: Subtask extrai_dados
[2024-10-29 15:11:05,115] {task_command.py:370} INFO - Running <TaskInstance: dados_climaticos.extrai_dados scheduled__2024-10-07T00:00:00+00:00 [running]> on host LAPTOP-SNAE0A1O.
[2024-10-29 15:11:05,151] {taskinstance.py:1569} INFO - Exporting the following env vars:
AIRFLOW_CTX_DAG_OWNER=airflow
AIRFLOW_CTX_DAG_ID=dados_climaticos
AIRFLOW_CTX_TASK_ID=extrai_dados
AIRFLOW_CTX_EXECUTION_DATE=2024-10-07T00:00:00+00:00
AIRFLOW_CTX_TRY_NUMBER=1
AIRFLOW_CTX_DAG_RUN_ID=scheduled__2024-10-07T00:00:00+00:00
[2024-10-29 15:11:06,027] {taskinstance.py:1889} ERROR - Task failed with exception
Traceback (most recent call last):
  File "/root/Documentos/airflow/venv/lib/python3.9/site-packages/airflow/operators/python.py", line 171, in execute
    return_value = self.execute_callable()
  File "/root/Documentos/airflow/venv/lib/python3.9/site-packages/airflow/operators/python.py", line 189, in execute_callable
    return self.python_callable(*self.op_args, **self.op_kwargs)
  File "/root/Documentos/airflow/dags/dados_climaticos.py", line 27, in extrai_dados
    dados = pd.read_csv(URL)
  File "/root/Documentos/airflow/venv/lib/python3.9/site-packages/pandas/io/parsers/readers.py", line 1026, in read_csv
    return _read(filepath_or_buffer, kwds)
  File "/root/Documentos/airflow/venv/lib/python3.9/site-packages/pandas/io/parsers/readers.py", line 620, in _read
    parser = TextFileReader(filepath_or_buffer, **kwds)
  File "/root/Documentos/airflow/venv/lib/python3.9/site-packages/pandas/io/parsers/readers.py", line 1620, in __init__
    self._engine = self._make_engine(f, self.engine)
  File "/root/Documentos/airflow/venv/lib/python3.9/site-packages/pandas/io/parsers/readers.py", line 1880, in _make_engine
    self.handles = get_handle(
  File "/root/Documentos/airflow/venv/lib/python3.9/site-packages/pandas/io/common.py", line 728, in get_handle
    ioargs = _get_filepath_or_buffer(
  File "/root/Documentos/airflow/venv/lib/python3.9/site-packages/pandas/io/common.py", line 384, in _get_filepath_or_buffer
    with urlopen(req_info) as req:
  File "/root/Documentos/airflow/venv/lib/python3.9/site-packages/pandas/io/common.py", line 289, in urlopen
    return urllib.request.urlopen(*args, **kwargs)
  File "/usr/lib/python3.9/urllib/request.py", line 214, in urlopen
    return opener.open(url, data, timeout)
  File "/usr/lib/python3.9/urllib/request.py", line 523, in open
    response = meth(req, response)
  File "/usr/lib/python3.9/urllib/request.py", line 632, in http_response
    response = self.parent.error(
  File "/usr/lib/python3.9/urllib/request.py", line 561, in error
    return self._call_chain(*args)
  File "/usr/lib/python3.9/urllib/request.py", line 494, in _call_chain
    result = func(*args)
  File "/usr/lib/python3.9/urllib/request.py", line 641, in http_error_default
    raise HTTPError(req.full_url, code, msg, hdrs, fp)
urllib.error.HTTPError: HTTP Error 401: 
[2024-10-29 15:11:06,029] {taskinstance.py:1395} INFO - Marking task as FAILED. dag_id=dados_climaticos, task_id=extrai_dados, execution_date=20241007T000000, start_date=20241029T181105, end_date=20241029T181106
[2024-10-29 15:11:06,039] {standard_task_runner.py:92} ERROR - Failed to execute job 40 for task extrai_dados (HTTP Error 401: ; 121227)
[2024-10-29 15:11:06,067] {local_task_job.py:156} INFO - Task exited with return code 1
[2024-10-29 15:11:06,078] {local_task_job.py:273} INFO - 0 downstream tasks scheduled from follow-on schedule check
[2024-10-29 15:14:30,341] {taskinstance.py:1159} INFO - Dependencies all met for <TaskInstance: dados_climaticos.extrai_dados scheduled__2024-10-07T00:00:00+00:00 [queued]>
[2024-10-29 15:14:30,345] {taskinstance.py:1159} INFO - Dependencies all met for <TaskInstance: dados_climaticos.extrai_dados scheduled__2024-10-07T00:00:00+00:00 [queued]>
[2024-10-29 15:14:30,345] {taskinstance.py:1356} INFO - 
--------------------------------------------------------------------------------
[2024-10-29 15:14:30,345] {taskinstance.py:1357} INFO - Starting attempt 1 of 1
[2024-10-29 15:14:30,345] {taskinstance.py:1358} INFO - 
--------------------------------------------------------------------------------
[2024-10-29 15:14:30,356] {taskinstance.py:1377} INFO - Executing <Task(PythonOperator): extrai_dados> on 2024-10-07 00:00:00+00:00
[2024-10-29 15:14:30,359] {standard_task_runner.py:52} INFO - Started process 122925 to run task
[2024-10-29 15:14:30,361] {standard_task_runner.py:79} INFO - Running: ['airflow', 'tasks', 'run', 'dados_climaticos', 'extrai_dados', 'scheduled__2024-10-07T00:00:00+00:00', '--job-id', '40', '--raw', '--subdir', 'DAGS_FOLDER/dados_climaticos.py', '--cfg-path', '/tmp/tmpv_l67xad', '--error-file', '/tmp/tmptpz2v80s']
[2024-10-29 15:14:30,361] {standard_task_runner.py:80} INFO - Job 40: Subtask extrai_dados
[2024-10-29 15:14:30,386] {task_command.py:370} INFO - Running <TaskInstance: dados_climaticos.extrai_dados scheduled__2024-10-07T00:00:00+00:00 [running]> on host LAPTOP-SNAE0A1O.
[2024-10-29 15:14:30,423] {taskinstance.py:1569} INFO - Exporting the following env vars:
AIRFLOW_CTX_DAG_OWNER=airflow
AIRFLOW_CTX_DAG_ID=dados_climaticos
AIRFLOW_CTX_TASK_ID=extrai_dados
AIRFLOW_CTX_EXECUTION_DATE=2024-10-07T00:00:00+00:00
AIRFLOW_CTX_TRY_NUMBER=1
AIRFLOW_CTX_DAG_RUN_ID=scheduled__2024-10-07T00:00:00+00:00
[2024-10-29 15:14:31,208] {python.py:173} INFO - Done. Returned value was: None
[2024-10-29 15:14:31,212] {taskinstance.py:1395} INFO - Marking task as SUCCESS. dag_id=dados_climaticos, task_id=extrai_dados, execution_date=20241007T000000, start_date=20241029T181430, end_date=20241029T181431
[2024-10-29 15:14:31,256] {local_task_job.py:156} INFO - Task exited with return code 0
[2024-10-29 15:14:31,266] {local_task_job.py:273} INFO - 0 downstream tasks scheduled from follow-on schedule check
[2024-10-29 19:04:44,229] {taskinstance.py:1159} INFO - Dependencies all met for <TaskInstance: dados_climaticos.extrai_dados scheduled__2024-10-07T00:00:00+00:00 [queued]>
[2024-10-29 19:04:44,234] {taskinstance.py:1159} INFO - Dependencies all met for <TaskInstance: dados_climaticos.extrai_dados scheduled__2024-10-07T00:00:00+00:00 [queued]>
[2024-10-29 19:04:44,234] {taskinstance.py:1356} INFO - 
--------------------------------------------------------------------------------
[2024-10-29 19:04:44,234] {taskinstance.py:1357} INFO - Starting attempt 1 of 1
[2024-10-29 19:04:44,234] {taskinstance.py:1358} INFO - 
--------------------------------------------------------------------------------
[2024-10-29 19:04:44,247] {taskinstance.py:1377} INFO - Executing <Task(PythonOperator): extrai_dados> on 2024-10-07 00:00:00+00:00
[2024-10-29 19:04:44,250] {standard_task_runner.py:52} INFO - Started process 54303 to run task
[2024-10-29 19:04:44,252] {standard_task_runner.py:79} INFO - Running: ['airflow', 'tasks', 'run', 'dados_climaticos', 'extrai_dados', 'scheduled__2024-10-07T00:00:00+00:00', '--job-id', '56', '--raw', '--subdir', 'DAGS_FOLDER/dados_climaticos.py', '--cfg-path', '/tmp/tmpiqv35yvr', '--error-file', '/tmp/tmp3tohe2gy']
[2024-10-29 19:04:44,252] {standard_task_runner.py:80} INFO - Job 56: Subtask extrai_dados
[2024-10-29 19:04:44,277] {task_command.py:370} INFO - Running <TaskInstance: dados_climaticos.extrai_dados scheduled__2024-10-07T00:00:00+00:00 [running]> on host LAPTOP-SNAE0A1O.
[2024-10-29 19:04:44,312] {taskinstance.py:1569} INFO - Exporting the following env vars:
AIRFLOW_CTX_DAG_OWNER=airflow
AIRFLOW_CTX_DAG_ID=dados_climaticos
AIRFLOW_CTX_TASK_ID=extrai_dados
AIRFLOW_CTX_EXECUTION_DATE=2024-10-07T00:00:00+00:00
AIRFLOW_CTX_TRY_NUMBER=1
AIRFLOW_CTX_DAG_RUN_ID=scheduled__2024-10-07T00:00:00+00:00
[2024-10-29 19:04:45,193] {python.py:173} INFO - Done. Returned value was: None
[2024-10-29 19:04:45,197] {taskinstance.py:1395} INFO - Marking task as SUCCESS. dag_id=dados_climaticos, task_id=extrai_dados, execution_date=20241007T000000, start_date=20241029T220444, end_date=20241029T220445
[2024-10-29 19:04:45,227] {local_task_job.py:156} INFO - Task exited with return code 0
[2024-10-29 19:04:45,236] {local_task_job.py:273} INFO - 0 downstream tasks scheduled from follow-on schedule check
