[2024-10-29 14:50:19,390] {taskinstance.py:1159} INFO - Dependencies all met for <TaskInstance: dados_climaticos.extrai_dados scheduled__2024-10-14T00:00:00+00:00 [queued]>
[2024-10-29 14:50:19,394] {taskinstance.py:1159} INFO - Dependencies all met for <TaskInstance: dados_climaticos.extrai_dados scheduled__2024-10-14T00:00:00+00:00 [queued]>
[2024-10-29 14:50:19,395] {taskinstance.py:1356} INFO - 
--------------------------------------------------------------------------------
[2024-10-29 14:50:19,395] {taskinstance.py:1357} INFO - Starting attempt 1 of 1
[2024-10-29 14:50:19,395] {taskinstance.py:1358} INFO - 
--------------------------------------------------------------------------------
[2024-10-29 14:50:19,407] {taskinstance.py:1377} INFO - Executing <Task(PythonOperator): extrai_dados> on 2024-10-14 00:00:00+00:00
[2024-10-29 14:50:19,410] {standard_task_runner.py:52} INFO - Started process 111073 to run task
[2024-10-29 14:50:19,411] {standard_task_runner.py:79} INFO - Running: ['airflow', 'tasks', 'run', 'dados_climaticos', 'extrai_dados', 'scheduled__2024-10-14T00:00:00+00:00', '--job-id', '41', '--raw', '--subdir', 'DAGS_FOLDER/dados_climaticos.py', '--cfg-path', '/tmp/tmppp253v64', '--error-file', '/tmp/tmp4m2cmy3a']
[2024-10-29 14:50:19,412] {standard_task_runner.py:80} INFO - Job 41: Subtask extrai_dados
[2024-10-29 14:50:19,438] {task_command.py:370} INFO - Running <TaskInstance: dados_climaticos.extrai_dados scheduled__2024-10-14T00:00:00+00:00 [running]> on host LAPTOP-SNAE0A1O.
[2024-10-29 14:50:19,458] {taskinstance.py:1889} ERROR - Task failed with exception
Traceback (most recent call last):
  File "/root/Documentos/airflow/venv/lib/python3.9/site-packages/airflow/models/taskinstance.py", line 1451, in _run_raw_task
    self._execute_task_with_callbacks(context, test_mode)
  File "/root/Documentos/airflow/venv/lib/python3.9/site-packages/airflow/models/taskinstance.py", line 1555, in _execute_task_with_callbacks
    task_orig = self.render_templates(context=context)
  File "/root/Documentos/airflow/venv/lib/python3.9/site-packages/airflow/models/taskinstance.py", line 2212, in render_templates
    rendered_task = self.task.render_template_fields(context)
  File "/root/Documentos/airflow/venv/lib/python3.9/site-packages/airflow/models/baseoperator.py", line 1185, in render_template_fields
    self._do_render_template_fields(self, self.template_fields, context, jinja_env, set())
  File "/root/Documentos/airflow/venv/lib/python3.9/site-packages/airflow/utils/session.py", line 71, in wrapper
    return func(*args, session=session, **kwargs)
  File "/root/Documentos/airflow/venv/lib/python3.9/site-packages/airflow/models/abstractoperator.py", line 344, in _do_render_template_fields
    rendered_content = self.render_template(
  File "/root/Documentos/airflow/venv/lib/python3.9/site-packages/airflow/models/abstractoperator.py", line 404, in render_template
    return {key: self.render_template(value, context, jinja_env) for key, value in value.items()}
  File "/root/Documentos/airflow/venv/lib/python3.9/site-packages/airflow/models/abstractoperator.py", line 404, in <dictcomp>
    return {key: self.render_template(value, context, jinja_env) for key, value in value.items()}
  File "/root/Documentos/airflow/venv/lib/python3.9/site-packages/airflow/models/abstractoperator.py", line 387, in render_template
    template = jinja_env.from_string(value)
  File "/root/Documentos/airflow/venv/lib/python3.9/site-packages/jinja2/environment.py", line 1092, in from_string
    return cls.from_code(self, self.compile(source), gs, None)
  File "/root/Documentos/airflow/venv/lib/python3.9/site-packages/jinja2/environment.py", line 757, in compile
    self.handle_exception(source=source_hint)
  File "/root/Documentos/airflow/venv/lib/python3.9/site-packages/jinja2/environment.py", line 925, in handle_exception
    raise rewrite_traceback_stack(source=source)
  File "<unknown>", line 1, in template
jinja2.exceptions.TemplateSyntaxError: unexpected char '"' at 29
[2024-10-29 14:50:19,461] {taskinstance.py:1395} INFO - Marking task as FAILED. dag_id=dados_climaticos, task_id=extrai_dados, execution_date=20241014T000000, start_date=20241029T175019, end_date=20241029T175019
[2024-10-29 14:50:19,471] {standard_task_runner.py:92} ERROR - Failed to execute job 41 for task extrai_dados (unexpected char '"' at 29; 111073)
[2024-10-29 14:50:19,504] {local_task_job.py:156} INFO - Task exited with return code 1
[2024-10-29 14:50:19,514] {local_task_job.py:273} INFO - 0 downstream tasks scheduled from follow-on schedule check
[2024-10-29 14:53:46,918] {taskinstance.py:1159} INFO - Dependencies all met for <TaskInstance: dados_climaticos.extrai_dados scheduled__2024-10-14T00:00:00+00:00 [queued]>
[2024-10-29 14:53:46,923] {taskinstance.py:1159} INFO - Dependencies all met for <TaskInstance: dados_climaticos.extrai_dados scheduled__2024-10-14T00:00:00+00:00 [queued]>
[2024-10-29 14:53:46,923] {taskinstance.py:1356} INFO - 
--------------------------------------------------------------------------------
[2024-10-29 14:53:46,923] {taskinstance.py:1357} INFO - Starting attempt 1 of 1
[2024-10-29 14:53:46,923] {taskinstance.py:1358} INFO - 
--------------------------------------------------------------------------------
[2024-10-29 14:53:46,934] {taskinstance.py:1377} INFO - Executing <Task(PythonOperator): extrai_dados> on 2024-10-14 00:00:00+00:00
[2024-10-29 14:53:46,937] {standard_task_runner.py:52} INFO - Started process 112793 to run task
[2024-10-29 14:53:46,939] {standard_task_runner.py:79} INFO - Running: ['airflow', 'tasks', 'run', 'dados_climaticos', 'extrai_dados', 'scheduled__2024-10-14T00:00:00+00:00', '--job-id', '41', '--raw', '--subdir', 'DAGS_FOLDER/dados_climaticos.py', '--cfg-path', '/tmp/tmpmycitkt6', '--error-file', '/tmp/tmpuejd01rj']
[2024-10-29 14:53:46,940] {standard_task_runner.py:80} INFO - Job 41: Subtask extrai_dados
[2024-10-29 14:53:46,966] {task_command.py:370} INFO - Running <TaskInstance: dados_climaticos.extrai_dados scheduled__2024-10-14T00:00:00+00:00 [running]> on host LAPTOP-SNAE0A1O.
[2024-10-29 14:53:46,984] {taskinstance.py:1889} ERROR - Task failed with exception
Traceback (most recent call last):
  File "/root/Documentos/airflow/venv/lib/python3.9/site-packages/airflow/models/taskinstance.py", line 1451, in _run_raw_task
    self._execute_task_with_callbacks(context, test_mode)
  File "/root/Documentos/airflow/venv/lib/python3.9/site-packages/airflow/models/taskinstance.py", line 1555, in _execute_task_with_callbacks
    task_orig = self.render_templates(context=context)
  File "/root/Documentos/airflow/venv/lib/python3.9/site-packages/airflow/models/taskinstance.py", line 2212, in render_templates
    rendered_task = self.task.render_template_fields(context)
  File "/root/Documentos/airflow/venv/lib/python3.9/site-packages/airflow/models/baseoperator.py", line 1185, in render_template_fields
    self._do_render_template_fields(self, self.template_fields, context, jinja_env, set())
  File "/root/Documentos/airflow/venv/lib/python3.9/site-packages/airflow/utils/session.py", line 71, in wrapper
    return func(*args, session=session, **kwargs)
  File "/root/Documentos/airflow/venv/lib/python3.9/site-packages/airflow/models/abstractoperator.py", line 344, in _do_render_template_fields
    rendered_content = self.render_template(
  File "/root/Documentos/airflow/venv/lib/python3.9/site-packages/airflow/models/abstractoperator.py", line 404, in render_template
    return {key: self.render_template(value, context, jinja_env) for key, value in value.items()}
  File "/root/Documentos/airflow/venv/lib/python3.9/site-packages/airflow/models/abstractoperator.py", line 404, in <dictcomp>
    return {key: self.render_template(value, context, jinja_env) for key, value in value.items()}
  File "/root/Documentos/airflow/venv/lib/python3.9/site-packages/airflow/models/abstractoperator.py", line 387, in render_template
    template = jinja_env.from_string(value)
  File "/root/Documentos/airflow/venv/lib/python3.9/site-packages/jinja2/environment.py", line 1092, in from_string
    return cls.from_code(self, self.compile(source), gs, None)
  File "/root/Documentos/airflow/venv/lib/python3.9/site-packages/jinja2/environment.py", line 757, in compile
    self.handle_exception(source=source_hint)
  File "/root/Documentos/airflow/venv/lib/python3.9/site-packages/jinja2/environment.py", line 925, in handle_exception
    raise rewrite_traceback_stack(source=source)
  File "<unknown>", line 1, in template
jinja2.exceptions.TemplateSyntaxError: unexpected char '"' at 29
[2024-10-29 14:53:46,987] {taskinstance.py:1395} INFO - Marking task as FAILED. dag_id=dados_climaticos, task_id=extrai_dados, execution_date=20241014T000000, start_date=20241029T175346, end_date=20241029T175346
[2024-10-29 14:53:46,997] {standard_task_runner.py:92} ERROR - Failed to execute job 41 for task extrai_dados (unexpected char '"' at 29; 112793)
[2024-10-29 14:53:47,031] {local_task_job.py:156} INFO - Task exited with return code 1
[2024-10-29 14:53:47,042] {local_task_job.py:273} INFO - 0 downstream tasks scheduled from follow-on schedule check
[2024-10-29 14:56:52,764] {taskinstance.py:1159} INFO - Dependencies all met for <TaskInstance: dados_climaticos.extrai_dados scheduled__2024-10-14T00:00:00+00:00 [queued]>
[2024-10-29 14:56:52,769] {taskinstance.py:1159} INFO - Dependencies all met for <TaskInstance: dados_climaticos.extrai_dados scheduled__2024-10-14T00:00:00+00:00 [queued]>
[2024-10-29 14:56:52,769] {taskinstance.py:1356} INFO - 
--------------------------------------------------------------------------------
[2024-10-29 14:56:52,769] {taskinstance.py:1357} INFO - Starting attempt 1 of 1
[2024-10-29 14:56:52,769] {taskinstance.py:1358} INFO - 
--------------------------------------------------------------------------------
[2024-10-29 14:56:52,780] {taskinstance.py:1377} INFO - Executing <Task(PythonOperator): extrai_dados> on 2024-10-14 00:00:00+00:00
[2024-10-29 14:56:52,783] {standard_task_runner.py:52} INFO - Started process 114330 to run task
[2024-10-29 14:56:52,784] {standard_task_runner.py:79} INFO - Running: ['airflow', 'tasks', 'run', 'dados_climaticos', 'extrai_dados', 'scheduled__2024-10-14T00:00:00+00:00', '--job-id', '41', '--raw', '--subdir', 'DAGS_FOLDER/dados_climaticos.py', '--cfg-path', '/tmp/tmpih1vk22l', '--error-file', '/tmp/tmpwt38pg5_']
[2024-10-29 14:56:52,785] {standard_task_runner.py:80} INFO - Job 41: Subtask extrai_dados
[2024-10-29 14:56:52,808] {task_command.py:370} INFO - Running <TaskInstance: dados_climaticos.extrai_dados scheduled__2024-10-14T00:00:00+00:00 [running]> on host LAPTOP-SNAE0A1O.
[2024-10-29 14:56:52,827] {taskinstance.py:1889} ERROR - Task failed with exception
Traceback (most recent call last):
  File "/root/Documentos/airflow/venv/lib/python3.9/site-packages/airflow/models/taskinstance.py", line 1451, in _run_raw_task
    self._execute_task_with_callbacks(context, test_mode)
  File "/root/Documentos/airflow/venv/lib/python3.9/site-packages/airflow/models/taskinstance.py", line 1555, in _execute_task_with_callbacks
    task_orig = self.render_templates(context=context)
  File "/root/Documentos/airflow/venv/lib/python3.9/site-packages/airflow/models/taskinstance.py", line 2212, in render_templates
    rendered_task = self.task.render_template_fields(context)
  File "/root/Documentos/airflow/venv/lib/python3.9/site-packages/airflow/models/baseoperator.py", line 1185, in render_template_fields
    self._do_render_template_fields(self, self.template_fields, context, jinja_env, set())
  File "/root/Documentos/airflow/venv/lib/python3.9/site-packages/airflow/utils/session.py", line 71, in wrapper
    return func(*args, session=session, **kwargs)
  File "/root/Documentos/airflow/venv/lib/python3.9/site-packages/airflow/models/abstractoperator.py", line 344, in _do_render_template_fields
    rendered_content = self.render_template(
  File "/root/Documentos/airflow/venv/lib/python3.9/site-packages/airflow/models/abstractoperator.py", line 404, in render_template
    return {key: self.render_template(value, context, jinja_env) for key, value in value.items()}
  File "/root/Documentos/airflow/venv/lib/python3.9/site-packages/airflow/models/abstractoperator.py", line 404, in <dictcomp>
    return {key: self.render_template(value, context, jinja_env) for key, value in value.items()}
  File "/root/Documentos/airflow/venv/lib/python3.9/site-packages/airflow/models/abstractoperator.py", line 387, in render_template
    template = jinja_env.from_string(value)
  File "/root/Documentos/airflow/venv/lib/python3.9/site-packages/jinja2/environment.py", line 1092, in from_string
    return cls.from_code(self, self.compile(source), gs, None)
  File "/root/Documentos/airflow/venv/lib/python3.9/site-packages/jinja2/environment.py", line 757, in compile
    self.handle_exception(source=source_hint)
  File "/root/Documentos/airflow/venv/lib/python3.9/site-packages/jinja2/environment.py", line 925, in handle_exception
    raise rewrite_traceback_stack(source=source)
  File "<unknown>", line 1, in template
jinja2.exceptions.TemplateSyntaxError: unexpected char '"' at 29
[2024-10-29 14:56:52,830] {taskinstance.py:1395} INFO - Marking task as FAILED. dag_id=dados_climaticos, task_id=extrai_dados, execution_date=20241014T000000, start_date=20241029T175652, end_date=20241029T175652
[2024-10-29 14:56:52,840] {standard_task_runner.py:92} ERROR - Failed to execute job 41 for task extrai_dados (unexpected char '"' at 29; 114330)
[2024-10-29 14:56:52,877] {local_task_job.py:156} INFO - Task exited with return code 1
[2024-10-29 14:56:52,887] {local_task_job.py:273} INFO - 0 downstream tasks scheduled from follow-on schedule check
[2024-10-29 15:02:46,136] {taskinstance.py:1159} INFO - Dependencies all met for <TaskInstance: dados_climaticos.extrai_dados scheduled__2024-10-14T00:00:00+00:00 [queued]>
[2024-10-29 15:02:46,141] {taskinstance.py:1159} INFO - Dependencies all met for <TaskInstance: dados_climaticos.extrai_dados scheduled__2024-10-14T00:00:00+00:00 [queued]>
[2024-10-29 15:02:46,141] {taskinstance.py:1356} INFO - 
--------------------------------------------------------------------------------
[2024-10-29 15:02:46,141] {taskinstance.py:1357} INFO - Starting attempt 1 of 1
[2024-10-29 15:02:46,141] {taskinstance.py:1358} INFO - 
--------------------------------------------------------------------------------
[2024-10-29 15:02:46,153] {taskinstance.py:1377} INFO - Executing <Task(PythonOperator): extrai_dados> on 2024-10-14 00:00:00+00:00
[2024-10-29 15:02:46,156] {standard_task_runner.py:52} INFO - Started process 117156 to run task
[2024-10-29 15:02:46,158] {standard_task_runner.py:79} INFO - Running: ['airflow', 'tasks', 'run', 'dados_climaticos', 'extrai_dados', 'scheduled__2024-10-14T00:00:00+00:00', '--job-id', '41', '--raw', '--subdir', 'DAGS_FOLDER/dados_climaticos.py', '--cfg-path', '/tmp/tmpmbf9f4zw', '--error-file', '/tmp/tmpiy1d1vnu']
[2024-10-29 15:02:46,158] {standard_task_runner.py:80} INFO - Job 41: Subtask extrai_dados
[2024-10-29 15:02:46,182] {task_command.py:370} INFO - Running <TaskInstance: dados_climaticos.extrai_dados scheduled__2024-10-14T00:00:00+00:00 [running]> on host LAPTOP-SNAE0A1O.
[2024-10-29 15:02:46,200] {taskinstance.py:1889} ERROR - Task failed with exception
Traceback (most recent call last):
  File "/root/Documentos/airflow/venv/lib/python3.9/site-packages/airflow/models/taskinstance.py", line 1451, in _run_raw_task
    self._execute_task_with_callbacks(context, test_mode)
  File "/root/Documentos/airflow/venv/lib/python3.9/site-packages/airflow/models/taskinstance.py", line 1555, in _execute_task_with_callbacks
    task_orig = self.render_templates(context=context)
  File "/root/Documentos/airflow/venv/lib/python3.9/site-packages/airflow/models/taskinstance.py", line 2212, in render_templates
    rendered_task = self.task.render_template_fields(context)
  File "/root/Documentos/airflow/venv/lib/python3.9/site-packages/airflow/models/baseoperator.py", line 1185, in render_template_fields
    self._do_render_template_fields(self, self.template_fields, context, jinja_env, set())
  File "/root/Documentos/airflow/venv/lib/python3.9/site-packages/airflow/utils/session.py", line 71, in wrapper
    return func(*args, session=session, **kwargs)
  File "/root/Documentos/airflow/venv/lib/python3.9/site-packages/airflow/models/abstractoperator.py", line 344, in _do_render_template_fields
    rendered_content = self.render_template(
  File "/root/Documentos/airflow/venv/lib/python3.9/site-packages/airflow/models/abstractoperator.py", line 404, in render_template
    return {key: self.render_template(value, context, jinja_env) for key, value in value.items()}
  File "/root/Documentos/airflow/venv/lib/python3.9/site-packages/airflow/models/abstractoperator.py", line 404, in <dictcomp>
    return {key: self.render_template(value, context, jinja_env) for key, value in value.items()}
  File "/root/Documentos/airflow/venv/lib/python3.9/site-packages/airflow/models/abstractoperator.py", line 387, in render_template
    template = jinja_env.from_string(value)
  File "/root/Documentos/airflow/venv/lib/python3.9/site-packages/jinja2/environment.py", line 1092, in from_string
    return cls.from_code(self, self.compile(source), gs, None)
  File "/root/Documentos/airflow/venv/lib/python3.9/site-packages/jinja2/environment.py", line 757, in compile
    self.handle_exception(source=source_hint)
  File "/root/Documentos/airflow/venv/lib/python3.9/site-packages/jinja2/environment.py", line 925, in handle_exception
    raise rewrite_traceback_stack(source=source)
  File "<unknown>", line 1, in template
jinja2.exceptions.TemplateSyntaxError: unexpected char '"' at 29
[2024-10-29 15:02:46,203] {taskinstance.py:1395} INFO - Marking task as FAILED. dag_id=dados_climaticos, task_id=extrai_dados, execution_date=20241014T000000, start_date=20241029T180246, end_date=20241029T180246
[2024-10-29 15:02:46,213] {standard_task_runner.py:92} ERROR - Failed to execute job 41 for task extrai_dados (unexpected char '"' at 29; 117156)
[2024-10-29 15:02:46,250] {local_task_job.py:156} INFO - Task exited with return code 1
[2024-10-29 15:02:46,261] {local_task_job.py:273} INFO - 0 downstream tasks scheduled from follow-on schedule check
[2024-10-29 15:05:40,300] {taskinstance.py:1159} INFO - Dependencies all met for <TaskInstance: dados_climaticos.extrai_dados scheduled__2024-10-14T00:00:00+00:00 [queued]>
[2024-10-29 15:05:40,304] {taskinstance.py:1159} INFO - Dependencies all met for <TaskInstance: dados_climaticos.extrai_dados scheduled__2024-10-14T00:00:00+00:00 [queued]>
[2024-10-29 15:05:40,305] {taskinstance.py:1356} INFO - 
--------------------------------------------------------------------------------
[2024-10-29 15:05:40,305] {taskinstance.py:1357} INFO - Starting attempt 1 of 1
[2024-10-29 15:05:40,305] {taskinstance.py:1358} INFO - 
--------------------------------------------------------------------------------
[2024-10-29 15:05:40,316] {taskinstance.py:1377} INFO - Executing <Task(PythonOperator): extrai_dados> on 2024-10-14 00:00:00+00:00
[2024-10-29 15:05:40,318] {standard_task_runner.py:52} INFO - Started process 118630 to run task
[2024-10-29 15:05:40,320] {standard_task_runner.py:79} INFO - Running: ['airflow', 'tasks', 'run', 'dados_climaticos', 'extrai_dados', 'scheduled__2024-10-14T00:00:00+00:00', '--job-id', '41', '--raw', '--subdir', 'DAGS_FOLDER/dados_climaticos.py', '--cfg-path', '/tmp/tmpb97sdh6v', '--error-file', '/tmp/tmpcnldplkh']
[2024-10-29 15:05:40,321] {standard_task_runner.py:80} INFO - Job 41: Subtask extrai_dados
[2024-10-29 15:05:40,345] {task_command.py:370} INFO - Running <TaskInstance: dados_climaticos.extrai_dados scheduled__2024-10-14T00:00:00+00:00 [running]> on host LAPTOP-SNAE0A1O.
[2024-10-29 15:05:40,363] {taskinstance.py:1889} ERROR - Task failed with exception
Traceback (most recent call last):
  File "/root/Documentos/airflow/venv/lib/python3.9/site-packages/airflow/models/taskinstance.py", line 1451, in _run_raw_task
    self._execute_task_with_callbacks(context, test_mode)
  File "/root/Documentos/airflow/venv/lib/python3.9/site-packages/airflow/models/taskinstance.py", line 1555, in _execute_task_with_callbacks
    task_orig = self.render_templates(context=context)
  File "/root/Documentos/airflow/venv/lib/python3.9/site-packages/airflow/models/taskinstance.py", line 2212, in render_templates
    rendered_task = self.task.render_template_fields(context)
  File "/root/Documentos/airflow/venv/lib/python3.9/site-packages/airflow/models/baseoperator.py", line 1185, in render_template_fields
    self._do_render_template_fields(self, self.template_fields, context, jinja_env, set())
  File "/root/Documentos/airflow/venv/lib/python3.9/site-packages/airflow/utils/session.py", line 71, in wrapper
    return func(*args, session=session, **kwargs)
  File "/root/Documentos/airflow/venv/lib/python3.9/site-packages/airflow/models/abstractoperator.py", line 344, in _do_render_template_fields
    rendered_content = self.render_template(
  File "/root/Documentos/airflow/venv/lib/python3.9/site-packages/airflow/models/abstractoperator.py", line 404, in render_template
    return {key: self.render_template(value, context, jinja_env) for key, value in value.items()}
  File "/root/Documentos/airflow/venv/lib/python3.9/site-packages/airflow/models/abstractoperator.py", line 404, in <dictcomp>
    return {key: self.render_template(value, context, jinja_env) for key, value in value.items()}
  File "/root/Documentos/airflow/venv/lib/python3.9/site-packages/airflow/models/abstractoperator.py", line 387, in render_template
    template = jinja_env.from_string(value)
  File "/root/Documentos/airflow/venv/lib/python3.9/site-packages/jinja2/environment.py", line 1092, in from_string
    return cls.from_code(self, self.compile(source), gs, None)
  File "/root/Documentos/airflow/venv/lib/python3.9/site-packages/jinja2/environment.py", line 757, in compile
    self.handle_exception(source=source_hint)
  File "/root/Documentos/airflow/venv/lib/python3.9/site-packages/jinja2/environment.py", line 925, in handle_exception
    raise rewrite_traceback_stack(source=source)
  File "<unknown>", line 1, in template
jinja2.exceptions.TemplateSyntaxError: unexpected char '"' at 29
[2024-10-29 15:05:40,365] {taskinstance.py:1395} INFO - Marking task as FAILED. dag_id=dados_climaticos, task_id=extrai_dados, execution_date=20241014T000000, start_date=20241029T180540, end_date=20241029T180540
[2024-10-29 15:05:40,375] {standard_task_runner.py:92} ERROR - Failed to execute job 41 for task extrai_dados (unexpected char '"' at 29; 118630)
[2024-10-29 15:05:40,412] {local_task_job.py:156} INFO - Task exited with return code 1
[2024-10-29 15:05:40,422] {local_task_job.py:273} INFO - 0 downstream tasks scheduled from follow-on schedule check
[2024-10-29 15:11:07,218] {taskinstance.py:1159} INFO - Dependencies all met for <TaskInstance: dados_climaticos.extrai_dados scheduled__2024-10-14T00:00:00+00:00 [queued]>
[2024-10-29 15:11:07,223] {taskinstance.py:1159} INFO - Dependencies all met for <TaskInstance: dados_climaticos.extrai_dados scheduled__2024-10-14T00:00:00+00:00 [queued]>
[2024-10-29 15:11:07,223] {taskinstance.py:1356} INFO - 
--------------------------------------------------------------------------------
[2024-10-29 15:11:07,223] {taskinstance.py:1357} INFO - Starting attempt 1 of 1
[2024-10-29 15:11:07,223] {taskinstance.py:1358} INFO - 
--------------------------------------------------------------------------------
[2024-10-29 15:11:07,235] {taskinstance.py:1377} INFO - Executing <Task(PythonOperator): extrai_dados> on 2024-10-14 00:00:00+00:00
[2024-10-29 15:11:07,238] {standard_task_runner.py:52} INFO - Started process 121260 to run task
[2024-10-29 15:11:07,239] {standard_task_runner.py:79} INFO - Running: ['airflow', 'tasks', 'run', 'dados_climaticos', 'extrai_dados', 'scheduled__2024-10-14T00:00:00+00:00', '--job-id', '41', '--raw', '--subdir', 'DAGS_FOLDER/dados_climaticos.py', '--cfg-path', '/tmp/tmpwl8w9tiy', '--error-file', '/tmp/tmpixi2a7h6']
[2024-10-29 15:11:07,240] {standard_task_runner.py:80} INFO - Job 41: Subtask extrai_dados
[2024-10-29 15:11:07,264] {task_command.py:370} INFO - Running <TaskInstance: dados_climaticos.extrai_dados scheduled__2024-10-14T00:00:00+00:00 [running]> on host LAPTOP-SNAE0A1O.
[2024-10-29 15:11:07,298] {taskinstance.py:1569} INFO - Exporting the following env vars:
AIRFLOW_CTX_DAG_OWNER=airflow
AIRFLOW_CTX_DAG_ID=dados_climaticos
AIRFLOW_CTX_TASK_ID=extrai_dados
AIRFLOW_CTX_EXECUTION_DATE=2024-10-14T00:00:00+00:00
AIRFLOW_CTX_TRY_NUMBER=1
AIRFLOW_CTX_DAG_RUN_ID=scheduled__2024-10-14T00:00:00+00:00
[2024-10-29 15:11:07,929] {taskinstance.py:1889} ERROR - Task failed with exception
Traceback (most recent call last):
  File "/root/Documentos/airflow/venv/lib/python3.9/site-packages/airflow/operators/python.py", line 171, in execute
    return_value = self.execute_callable()
  File "/root/Documentos/airflow/venv/lib/python3.9/site-packages/airflow/operators/python.py", line 189, in execute_callable
    return self.python_callable(*self.op_args, **self.op_kwargs)
  File "/root/Documentos/airflow/dags/dados_climaticos.py", line 27, in extrai_dados
    dados = pd.read_csv(URL)
  File "/root/Documentos/airflow/venv/lib/python3.9/site-packages/pandas/io/parsers/readers.py", line 1026, in read_csv
    return _read(filepath_or_buffer, kwds)
  File "/root/Documentos/airflow/venv/lib/python3.9/site-packages/pandas/io/parsers/readers.py", line 620, in _read
    parser = TextFileReader(filepath_or_buffer, **kwds)
  File "/root/Documentos/airflow/venv/lib/python3.9/site-packages/pandas/io/parsers/readers.py", line 1620, in __init__
    self._engine = self._make_engine(f, self.engine)
  File "/root/Documentos/airflow/venv/lib/python3.9/site-packages/pandas/io/parsers/readers.py", line 1880, in _make_engine
    self.handles = get_handle(
  File "/root/Documentos/airflow/venv/lib/python3.9/site-packages/pandas/io/common.py", line 728, in get_handle
    ioargs = _get_filepath_or_buffer(
  File "/root/Documentos/airflow/venv/lib/python3.9/site-packages/pandas/io/common.py", line 384, in _get_filepath_or_buffer
    with urlopen(req_info) as req:
  File "/root/Documentos/airflow/venv/lib/python3.9/site-packages/pandas/io/common.py", line 289, in urlopen
    return urllib.request.urlopen(*args, **kwargs)
  File "/usr/lib/python3.9/urllib/request.py", line 214, in urlopen
    return opener.open(url, data, timeout)
  File "/usr/lib/python3.9/urllib/request.py", line 523, in open
    response = meth(req, response)
  File "/usr/lib/python3.9/urllib/request.py", line 632, in http_response
    response = self.parent.error(
  File "/usr/lib/python3.9/urllib/request.py", line 561, in error
    return self._call_chain(*args)
  File "/usr/lib/python3.9/urllib/request.py", line 494, in _call_chain
    result = func(*args)
  File "/usr/lib/python3.9/urllib/request.py", line 641, in http_error_default
    raise HTTPError(req.full_url, code, msg, hdrs, fp)
urllib.error.HTTPError: HTTP Error 401: 
[2024-10-29 15:11:07,932] {taskinstance.py:1395} INFO - Marking task as FAILED. dag_id=dados_climaticos, task_id=extrai_dados, execution_date=20241014T000000, start_date=20241029T181107, end_date=20241029T181107
[2024-10-29 15:11:07,943] {standard_task_runner.py:92} ERROR - Failed to execute job 41 for task extrai_dados (HTTP Error 401: ; 121260)
[2024-10-29 15:11:07,975] {local_task_job.py:156} INFO - Task exited with return code 1
[2024-10-29 15:11:07,985] {local_task_job.py:273} INFO - 0 downstream tasks scheduled from follow-on schedule check
[2024-10-29 15:14:32,422] {taskinstance.py:1159} INFO - Dependencies all met for <TaskInstance: dados_climaticos.extrai_dados scheduled__2024-10-14T00:00:00+00:00 [queued]>
[2024-10-29 15:14:32,427] {taskinstance.py:1159} INFO - Dependencies all met for <TaskInstance: dados_climaticos.extrai_dados scheduled__2024-10-14T00:00:00+00:00 [queued]>
[2024-10-29 15:14:32,427] {taskinstance.py:1356} INFO - 
--------------------------------------------------------------------------------
[2024-10-29 15:14:32,427] {taskinstance.py:1357} INFO - Starting attempt 1 of 1
[2024-10-29 15:14:32,427] {taskinstance.py:1358} INFO - 
--------------------------------------------------------------------------------
[2024-10-29 15:14:32,438] {taskinstance.py:1377} INFO - Executing <Task(PythonOperator): extrai_dados> on 2024-10-14 00:00:00+00:00
[2024-10-29 15:14:32,441] {standard_task_runner.py:52} INFO - Started process 122957 to run task
[2024-10-29 15:14:32,443] {standard_task_runner.py:79} INFO - Running: ['airflow', 'tasks', 'run', 'dados_climaticos', 'extrai_dados', 'scheduled__2024-10-14T00:00:00+00:00', '--job-id', '41', '--raw', '--subdir', 'DAGS_FOLDER/dados_climaticos.py', '--cfg-path', '/tmp/tmppexux2_f', '--error-file', '/tmp/tmp6p5ksixn']
[2024-10-29 15:14:32,443] {standard_task_runner.py:80} INFO - Job 41: Subtask extrai_dados
[2024-10-29 15:14:32,468] {task_command.py:370} INFO - Running <TaskInstance: dados_climaticos.extrai_dados scheduled__2024-10-14T00:00:00+00:00 [running]> on host LAPTOP-SNAE0A1O.
[2024-10-29 15:14:32,502] {taskinstance.py:1569} INFO - Exporting the following env vars:
AIRFLOW_CTX_DAG_OWNER=airflow
AIRFLOW_CTX_DAG_ID=dados_climaticos
AIRFLOW_CTX_TASK_ID=extrai_dados
AIRFLOW_CTX_EXECUTION_DATE=2024-10-14T00:00:00+00:00
AIRFLOW_CTX_TRY_NUMBER=1
AIRFLOW_CTX_DAG_RUN_ID=scheduled__2024-10-14T00:00:00+00:00
[2024-10-29 15:14:33,227] {python.py:173} INFO - Done. Returned value was: None
[2024-10-29 15:14:33,231] {taskinstance.py:1395} INFO - Marking task as SUCCESS. dag_id=dados_climaticos, task_id=extrai_dados, execution_date=20241014T000000, start_date=20241029T181432, end_date=20241029T181433
[2024-10-29 15:14:33,258] {local_task_job.py:156} INFO - Task exited with return code 0
[2024-10-29 15:14:33,269] {local_task_job.py:273} INFO - 0 downstream tasks scheduled from follow-on schedule check
[2024-10-29 19:04:46,438] {taskinstance.py:1159} INFO - Dependencies all met for <TaskInstance: dados_climaticos.extrai_dados scheduled__2024-10-14T00:00:00+00:00 [queued]>
[2024-10-29 19:04:46,443] {taskinstance.py:1159} INFO - Dependencies all met for <TaskInstance: dados_climaticos.extrai_dados scheduled__2024-10-14T00:00:00+00:00 [queued]>
[2024-10-29 19:04:46,443] {taskinstance.py:1356} INFO - 
--------------------------------------------------------------------------------
[2024-10-29 19:04:46,443] {taskinstance.py:1357} INFO - Starting attempt 1 of 1
[2024-10-29 19:04:46,443] {taskinstance.py:1358} INFO - 
--------------------------------------------------------------------------------
[2024-10-29 19:04:46,456] {taskinstance.py:1377} INFO - Executing <Task(PythonOperator): extrai_dados> on 2024-10-14 00:00:00+00:00
[2024-10-29 19:04:46,459] {standard_task_runner.py:52} INFO - Started process 54336 to run task
[2024-10-29 19:04:46,461] {standard_task_runner.py:79} INFO - Running: ['airflow', 'tasks', 'run', 'dados_climaticos', 'extrai_dados', 'scheduled__2024-10-14T00:00:00+00:00', '--job-id', '57', '--raw', '--subdir', 'DAGS_FOLDER/dados_climaticos.py', '--cfg-path', '/tmp/tmpspk0hzmx', '--error-file', '/tmp/tmpvj8e5qwz']
[2024-10-29 19:04:46,461] {standard_task_runner.py:80} INFO - Job 57: Subtask extrai_dados
[2024-10-29 19:04:46,486] {task_command.py:370} INFO - Running <TaskInstance: dados_climaticos.extrai_dados scheduled__2024-10-14T00:00:00+00:00 [running]> on host LAPTOP-SNAE0A1O.
[2024-10-29 19:04:46,524] {taskinstance.py:1569} INFO - Exporting the following env vars:
AIRFLOW_CTX_DAG_OWNER=airflow
AIRFLOW_CTX_DAG_ID=dados_climaticos
AIRFLOW_CTX_TASK_ID=extrai_dados
AIRFLOW_CTX_EXECUTION_DATE=2024-10-14T00:00:00+00:00
AIRFLOW_CTX_TRY_NUMBER=1
AIRFLOW_CTX_DAG_RUN_ID=scheduled__2024-10-14T00:00:00+00:00
[2024-10-29 19:04:47,210] {python.py:173} INFO - Done. Returned value was: None
[2024-10-29 19:04:47,214] {taskinstance.py:1395} INFO - Marking task as SUCCESS. dag_id=dados_climaticos, task_id=extrai_dados, execution_date=20241014T000000, start_date=20241029T220446, end_date=20241029T220447
[2024-10-29 19:04:47,237] {local_task_job.py:156} INFO - Task exited with return code 0
[2024-10-29 19:04:47,246] {local_task_job.py:273} INFO - 0 downstream tasks scheduled from follow-on schedule check
