[2024-10-29 14:50:15,701] {taskinstance.py:1159} INFO - Dependencies all met for <TaskInstance: dados_climaticos.extrai_dados scheduled__2024-09-30T00:00:00+00:00 [queued]>
[2024-10-29 14:50:15,705] {taskinstance.py:1159} INFO - Dependencies all met for <TaskInstance: dados_climaticos.extrai_dados scheduled__2024-09-30T00:00:00+00:00 [queued]>
[2024-10-29 14:50:15,705] {taskinstance.py:1356} INFO - 
--------------------------------------------------------------------------------
[2024-10-29 14:50:15,705] {taskinstance.py:1357} INFO - Starting attempt 1 of 1
[2024-10-29 14:50:15,705] {taskinstance.py:1358} INFO - 
--------------------------------------------------------------------------------
[2024-10-29 14:50:15,717] {taskinstance.py:1377} INFO - Executing <Task(PythonOperator): extrai_dados> on 2024-09-30 00:00:00+00:00
[2024-10-29 14:50:15,720] {standard_task_runner.py:52} INFO - Started process 110988 to run task
[2024-10-29 14:50:15,721] {standard_task_runner.py:79} INFO - Running: ['airflow', 'tasks', 'run', 'dados_climaticos', 'extrai_dados', 'scheduled__2024-09-30T00:00:00+00:00', '--job-id', '38', '--raw', '--subdir', 'DAGS_FOLDER/dados_climaticos.py', '--cfg-path', '/tmp/tmpwoqkbw25', '--error-file', '/tmp/tmp42ns0vn1']
[2024-10-29 14:50:15,722] {standard_task_runner.py:80} INFO - Job 38: Subtask extrai_dados
[2024-10-29 14:50:15,748] {task_command.py:370} INFO - Running <TaskInstance: dados_climaticos.extrai_dados scheduled__2024-09-30T00:00:00+00:00 [running]> on host LAPTOP-SNAE0A1O.
[2024-10-29 14:50:15,766] {taskinstance.py:1889} ERROR - Task failed with exception
Traceback (most recent call last):
  File "/root/Documentos/airflow/venv/lib/python3.9/site-packages/airflow/models/taskinstance.py", line 1451, in _run_raw_task
    self._execute_task_with_callbacks(context, test_mode)
  File "/root/Documentos/airflow/venv/lib/python3.9/site-packages/airflow/models/taskinstance.py", line 1555, in _execute_task_with_callbacks
    task_orig = self.render_templates(context=context)
  File "/root/Documentos/airflow/venv/lib/python3.9/site-packages/airflow/models/taskinstance.py", line 2212, in render_templates
    rendered_task = self.task.render_template_fields(context)
  File "/root/Documentos/airflow/venv/lib/python3.9/site-packages/airflow/models/baseoperator.py", line 1185, in render_template_fields
    self._do_render_template_fields(self, self.template_fields, context, jinja_env, set())
  File "/root/Documentos/airflow/venv/lib/python3.9/site-packages/airflow/utils/session.py", line 71, in wrapper
    return func(*args, session=session, **kwargs)
  File "/root/Documentos/airflow/venv/lib/python3.9/site-packages/airflow/models/abstractoperator.py", line 344, in _do_render_template_fields
    rendered_content = self.render_template(
  File "/root/Documentos/airflow/venv/lib/python3.9/site-packages/airflow/models/abstractoperator.py", line 404, in render_template
    return {key: self.render_template(value, context, jinja_env) for key, value in value.items()}
  File "/root/Documentos/airflow/venv/lib/python3.9/site-packages/airflow/models/abstractoperator.py", line 404, in <dictcomp>
    return {key: self.render_template(value, context, jinja_env) for key, value in value.items()}
  File "/root/Documentos/airflow/venv/lib/python3.9/site-packages/airflow/models/abstractoperator.py", line 387, in render_template
    template = jinja_env.from_string(value)
  File "/root/Documentos/airflow/venv/lib/python3.9/site-packages/jinja2/environment.py", line 1092, in from_string
    return cls.from_code(self, self.compile(source), gs, None)
  File "/root/Documentos/airflow/venv/lib/python3.9/site-packages/jinja2/environment.py", line 757, in compile
    self.handle_exception(source=source_hint)
  File "/root/Documentos/airflow/venv/lib/python3.9/site-packages/jinja2/environment.py", line 925, in handle_exception
    raise rewrite_traceback_stack(source=source)
  File "<unknown>", line 1, in template
jinja2.exceptions.TemplateSyntaxError: unexpected char '"' at 29
[2024-10-29 14:50:15,769] {taskinstance.py:1395} INFO - Marking task as FAILED. dag_id=dados_climaticos, task_id=extrai_dados, execution_date=20240930T000000, start_date=20241029T175015, end_date=20241029T175015
[2024-10-29 14:50:15,780] {standard_task_runner.py:92} ERROR - Failed to execute job 38 for task extrai_dados (unexpected char '"' at 29; 110988)
[2024-10-29 14:50:15,814] {local_task_job.py:156} INFO - Task exited with return code 1
[2024-10-29 14:50:15,825] {local_task_job.py:273} INFO - 0 downstream tasks scheduled from follow-on schedule check
[2024-10-29 14:53:43,079] {taskinstance.py:1159} INFO - Dependencies all met for <TaskInstance: dados_climaticos.extrai_dados scheduled__2024-09-30T00:00:00+00:00 [queued]>
[2024-10-29 14:53:43,084] {taskinstance.py:1159} INFO - Dependencies all met for <TaskInstance: dados_climaticos.extrai_dados scheduled__2024-09-30T00:00:00+00:00 [queued]>
[2024-10-29 14:53:43,084] {taskinstance.py:1356} INFO - 
--------------------------------------------------------------------------------
[2024-10-29 14:53:43,084] {taskinstance.py:1357} INFO - Starting attempt 1 of 1
[2024-10-29 14:53:43,084] {taskinstance.py:1358} INFO - 
--------------------------------------------------------------------------------
[2024-10-29 14:53:43,095] {taskinstance.py:1377} INFO - Executing <Task(PythonOperator): extrai_dados> on 2024-09-30 00:00:00+00:00
[2024-10-29 14:53:43,098] {standard_task_runner.py:52} INFO - Started process 112710 to run task
[2024-10-29 14:53:43,100] {standard_task_runner.py:79} INFO - Running: ['airflow', 'tasks', 'run', 'dados_climaticos', 'extrai_dados', 'scheduled__2024-09-30T00:00:00+00:00', '--job-id', '38', '--raw', '--subdir', 'DAGS_FOLDER/dados_climaticos.py', '--cfg-path', '/tmp/tmp36xnzk6_', '--error-file', '/tmp/tmp9n7g8nz9']
[2024-10-29 14:53:43,100] {standard_task_runner.py:80} INFO - Job 38: Subtask extrai_dados
[2024-10-29 14:53:43,126] {task_command.py:370} INFO - Running <TaskInstance: dados_climaticos.extrai_dados scheduled__2024-09-30T00:00:00+00:00 [running]> on host LAPTOP-SNAE0A1O.
[2024-10-29 14:53:43,144] {taskinstance.py:1889} ERROR - Task failed with exception
Traceback (most recent call last):
  File "/root/Documentos/airflow/venv/lib/python3.9/site-packages/airflow/models/taskinstance.py", line 1451, in _run_raw_task
    self._execute_task_with_callbacks(context, test_mode)
  File "/root/Documentos/airflow/venv/lib/python3.9/site-packages/airflow/models/taskinstance.py", line 1555, in _execute_task_with_callbacks
    task_orig = self.render_templates(context=context)
  File "/root/Documentos/airflow/venv/lib/python3.9/site-packages/airflow/models/taskinstance.py", line 2212, in render_templates
    rendered_task = self.task.render_template_fields(context)
  File "/root/Documentos/airflow/venv/lib/python3.9/site-packages/airflow/models/baseoperator.py", line 1185, in render_template_fields
    self._do_render_template_fields(self, self.template_fields, context, jinja_env, set())
  File "/root/Documentos/airflow/venv/lib/python3.9/site-packages/airflow/utils/session.py", line 71, in wrapper
    return func(*args, session=session, **kwargs)
  File "/root/Documentos/airflow/venv/lib/python3.9/site-packages/airflow/models/abstractoperator.py", line 344, in _do_render_template_fields
    rendered_content = self.render_template(
  File "/root/Documentos/airflow/venv/lib/python3.9/site-packages/airflow/models/abstractoperator.py", line 404, in render_template
    return {key: self.render_template(value, context, jinja_env) for key, value in value.items()}
  File "/root/Documentos/airflow/venv/lib/python3.9/site-packages/airflow/models/abstractoperator.py", line 404, in <dictcomp>
    return {key: self.render_template(value, context, jinja_env) for key, value in value.items()}
  File "/root/Documentos/airflow/venv/lib/python3.9/site-packages/airflow/models/abstractoperator.py", line 387, in render_template
    template = jinja_env.from_string(value)
  File "/root/Documentos/airflow/venv/lib/python3.9/site-packages/jinja2/environment.py", line 1092, in from_string
    return cls.from_code(self, self.compile(source), gs, None)
  File "/root/Documentos/airflow/venv/lib/python3.9/site-packages/jinja2/environment.py", line 757, in compile
    self.handle_exception(source=source_hint)
  File "/root/Documentos/airflow/venv/lib/python3.9/site-packages/jinja2/environment.py", line 925, in handle_exception
    raise rewrite_traceback_stack(source=source)
  File "<unknown>", line 1, in template
jinja2.exceptions.TemplateSyntaxError: unexpected char '"' at 29
[2024-10-29 14:53:43,147] {taskinstance.py:1395} INFO - Marking task as FAILED. dag_id=dados_climaticos, task_id=extrai_dados, execution_date=20240930T000000, start_date=20241029T175343, end_date=20241029T175343
[2024-10-29 14:53:43,157] {standard_task_runner.py:92} ERROR - Failed to execute job 38 for task extrai_dados (unexpected char '"' at 29; 112710)
[2024-10-29 14:53:43,192] {local_task_job.py:156} INFO - Task exited with return code 1
[2024-10-29 14:53:43,203] {local_task_job.py:273} INFO - 0 downstream tasks scheduled from follow-on schedule check
[2024-10-29 14:56:47,468] {taskinstance.py:1159} INFO - Dependencies all met for <TaskInstance: dados_climaticos.extrai_dados scheduled__2024-09-30T00:00:00+00:00 [queued]>
[2024-10-29 14:56:47,473] {taskinstance.py:1159} INFO - Dependencies all met for <TaskInstance: dados_climaticos.extrai_dados scheduled__2024-09-30T00:00:00+00:00 [queued]>
[2024-10-29 14:56:47,473] {taskinstance.py:1356} INFO - 
--------------------------------------------------------------------------------
[2024-10-29 14:56:47,474] {taskinstance.py:1357} INFO - Starting attempt 1 of 1
[2024-10-29 14:56:47,474] {taskinstance.py:1358} INFO - 
--------------------------------------------------------------------------------
[2024-10-29 14:56:47,484] {taskinstance.py:1377} INFO - Executing <Task(PythonOperator): extrai_dados> on 2024-09-30 00:00:00+00:00
[2024-10-29 14:56:47,487] {standard_task_runner.py:52} INFO - Started process 114252 to run task
[2024-10-29 14:56:47,488] {standard_task_runner.py:79} INFO - Running: ['airflow', 'tasks', 'run', 'dados_climaticos', 'extrai_dados', 'scheduled__2024-09-30T00:00:00+00:00', '--job-id', '38', '--raw', '--subdir', 'DAGS_FOLDER/dados_climaticos.py', '--cfg-path', '/tmp/tmpbxt9mzew', '--error-file', '/tmp/tmptxa6v5f0']
[2024-10-29 14:56:47,489] {standard_task_runner.py:80} INFO - Job 38: Subtask extrai_dados
[2024-10-29 14:56:47,513] {task_command.py:370} INFO - Running <TaskInstance: dados_climaticos.extrai_dados scheduled__2024-09-30T00:00:00+00:00 [running]> on host LAPTOP-SNAE0A1O.
[2024-10-29 14:56:47,530] {taskinstance.py:1889} ERROR - Task failed with exception
Traceback (most recent call last):
  File "/root/Documentos/airflow/venv/lib/python3.9/site-packages/airflow/models/taskinstance.py", line 1451, in _run_raw_task
    self._execute_task_with_callbacks(context, test_mode)
  File "/root/Documentos/airflow/venv/lib/python3.9/site-packages/airflow/models/taskinstance.py", line 1555, in _execute_task_with_callbacks
    task_orig = self.render_templates(context=context)
  File "/root/Documentos/airflow/venv/lib/python3.9/site-packages/airflow/models/taskinstance.py", line 2212, in render_templates
    rendered_task = self.task.render_template_fields(context)
  File "/root/Documentos/airflow/venv/lib/python3.9/site-packages/airflow/models/baseoperator.py", line 1185, in render_template_fields
    self._do_render_template_fields(self, self.template_fields, context, jinja_env, set())
  File "/root/Documentos/airflow/venv/lib/python3.9/site-packages/airflow/utils/session.py", line 71, in wrapper
    return func(*args, session=session, **kwargs)
  File "/root/Documentos/airflow/venv/lib/python3.9/site-packages/airflow/models/abstractoperator.py", line 344, in _do_render_template_fields
    rendered_content = self.render_template(
  File "/root/Documentos/airflow/venv/lib/python3.9/site-packages/airflow/models/abstractoperator.py", line 404, in render_template
    return {key: self.render_template(value, context, jinja_env) for key, value in value.items()}
  File "/root/Documentos/airflow/venv/lib/python3.9/site-packages/airflow/models/abstractoperator.py", line 404, in <dictcomp>
    return {key: self.render_template(value, context, jinja_env) for key, value in value.items()}
  File "/root/Documentos/airflow/venv/lib/python3.9/site-packages/airflow/models/abstractoperator.py", line 387, in render_template
    template = jinja_env.from_string(value)
  File "/root/Documentos/airflow/venv/lib/python3.9/site-packages/jinja2/environment.py", line 1092, in from_string
    return cls.from_code(self, self.compile(source), gs, None)
  File "/root/Documentos/airflow/venv/lib/python3.9/site-packages/jinja2/environment.py", line 757, in compile
    self.handle_exception(source=source_hint)
  File "/root/Documentos/airflow/venv/lib/python3.9/site-packages/jinja2/environment.py", line 925, in handle_exception
    raise rewrite_traceback_stack(source=source)
  File "<unknown>", line 1, in template
jinja2.exceptions.TemplateSyntaxError: unexpected char '"' at 29
[2024-10-29 14:56:47,532] {taskinstance.py:1395} INFO - Marking task as FAILED. dag_id=dados_climaticos, task_id=extrai_dados, execution_date=20240930T000000, start_date=20241029T175647, end_date=20241029T175647
[2024-10-29 14:56:47,542] {standard_task_runner.py:92} ERROR - Failed to execute job 38 for task extrai_dados (unexpected char '"' at 29; 114252)
[2024-10-29 14:56:47,581] {local_task_job.py:156} INFO - Task exited with return code 1
[2024-10-29 14:56:47,591] {local_task_job.py:273} INFO - 0 downstream tasks scheduled from follow-on schedule check
[2024-10-29 15:02:42,450] {taskinstance.py:1159} INFO - Dependencies all met for <TaskInstance: dados_climaticos.extrai_dados scheduled__2024-09-30T00:00:00+00:00 [queued]>
[2024-10-29 15:02:42,454] {taskinstance.py:1159} INFO - Dependencies all met for <TaskInstance: dados_climaticos.extrai_dados scheduled__2024-09-30T00:00:00+00:00 [queued]>
[2024-10-29 15:02:42,455] {taskinstance.py:1356} INFO - 
--------------------------------------------------------------------------------
[2024-10-29 15:02:42,455] {taskinstance.py:1357} INFO - Starting attempt 1 of 1
[2024-10-29 15:02:42,455] {taskinstance.py:1358} INFO - 
--------------------------------------------------------------------------------
[2024-10-29 15:02:42,466] {taskinstance.py:1377} INFO - Executing <Task(PythonOperator): extrai_dados> on 2024-09-30 00:00:00+00:00
[2024-10-29 15:02:42,469] {standard_task_runner.py:52} INFO - Started process 117079 to run task
[2024-10-29 15:02:42,471] {standard_task_runner.py:79} INFO - Running: ['airflow', 'tasks', 'run', 'dados_climaticos', 'extrai_dados', 'scheduled__2024-09-30T00:00:00+00:00', '--job-id', '38', '--raw', '--subdir', 'DAGS_FOLDER/dados_climaticos.py', '--cfg-path', '/tmp/tmpi7ed4r6r', '--error-file', '/tmp/tmp4dfrzc7q']
[2024-10-29 15:02:42,471] {standard_task_runner.py:80} INFO - Job 38: Subtask extrai_dados
[2024-10-29 15:02:42,496] {task_command.py:370} INFO - Running <TaskInstance: dados_climaticos.extrai_dados scheduled__2024-09-30T00:00:00+00:00 [running]> on host LAPTOP-SNAE0A1O.
[2024-10-29 15:02:42,513] {taskinstance.py:1889} ERROR - Task failed with exception
Traceback (most recent call last):
  File "/root/Documentos/airflow/venv/lib/python3.9/site-packages/airflow/models/taskinstance.py", line 1451, in _run_raw_task
    self._execute_task_with_callbacks(context, test_mode)
  File "/root/Documentos/airflow/venv/lib/python3.9/site-packages/airflow/models/taskinstance.py", line 1555, in _execute_task_with_callbacks
    task_orig = self.render_templates(context=context)
  File "/root/Documentos/airflow/venv/lib/python3.9/site-packages/airflow/models/taskinstance.py", line 2212, in render_templates
    rendered_task = self.task.render_template_fields(context)
  File "/root/Documentos/airflow/venv/lib/python3.9/site-packages/airflow/models/baseoperator.py", line 1185, in render_template_fields
    self._do_render_template_fields(self, self.template_fields, context, jinja_env, set())
  File "/root/Documentos/airflow/venv/lib/python3.9/site-packages/airflow/utils/session.py", line 71, in wrapper
    return func(*args, session=session, **kwargs)
  File "/root/Documentos/airflow/venv/lib/python3.9/site-packages/airflow/models/abstractoperator.py", line 344, in _do_render_template_fields
    rendered_content = self.render_template(
  File "/root/Documentos/airflow/venv/lib/python3.9/site-packages/airflow/models/abstractoperator.py", line 404, in render_template
    return {key: self.render_template(value, context, jinja_env) for key, value in value.items()}
  File "/root/Documentos/airflow/venv/lib/python3.9/site-packages/airflow/models/abstractoperator.py", line 404, in <dictcomp>
    return {key: self.render_template(value, context, jinja_env) for key, value in value.items()}
  File "/root/Documentos/airflow/venv/lib/python3.9/site-packages/airflow/models/abstractoperator.py", line 387, in render_template
    template = jinja_env.from_string(value)
  File "/root/Documentos/airflow/venv/lib/python3.9/site-packages/jinja2/environment.py", line 1092, in from_string
    return cls.from_code(self, self.compile(source), gs, None)
  File "/root/Documentos/airflow/venv/lib/python3.9/site-packages/jinja2/environment.py", line 757, in compile
    self.handle_exception(source=source_hint)
  File "/root/Documentos/airflow/venv/lib/python3.9/site-packages/jinja2/environment.py", line 925, in handle_exception
    raise rewrite_traceback_stack(source=source)
  File "<unknown>", line 1, in template
jinja2.exceptions.TemplateSyntaxError: unexpected char '"' at 29
[2024-10-29 15:02:42,516] {taskinstance.py:1395} INFO - Marking task as FAILED. dag_id=dados_climaticos, task_id=extrai_dados, execution_date=20240930T000000, start_date=20241029T180242, end_date=20241029T180242
[2024-10-29 15:02:42,526] {standard_task_runner.py:92} ERROR - Failed to execute job 38 for task extrai_dados (unexpected char '"' at 29; 117079)
[2024-10-29 15:02:42,563] {local_task_job.py:156} INFO - Task exited with return code 1
[2024-10-29 15:02:42,574] {local_task_job.py:273} INFO - 0 downstream tasks scheduled from follow-on schedule check
[2024-10-29 15:05:36,655] {taskinstance.py:1159} INFO - Dependencies all met for <TaskInstance: dados_climaticos.extrai_dados scheduled__2024-09-30T00:00:00+00:00 [queued]>
[2024-10-29 15:05:36,659] {taskinstance.py:1159} INFO - Dependencies all met for <TaskInstance: dados_climaticos.extrai_dados scheduled__2024-09-30T00:00:00+00:00 [queued]>
[2024-10-29 15:05:36,659] {taskinstance.py:1356} INFO - 
--------------------------------------------------------------------------------
[2024-10-29 15:05:36,659] {taskinstance.py:1357} INFO - Starting attempt 1 of 1
[2024-10-29 15:05:36,659] {taskinstance.py:1358} INFO - 
--------------------------------------------------------------------------------
[2024-10-29 15:05:36,671] {taskinstance.py:1377} INFO - Executing <Task(PythonOperator): extrai_dados> on 2024-09-30 00:00:00+00:00
[2024-10-29 15:05:36,674] {standard_task_runner.py:52} INFO - Started process 118548 to run task
[2024-10-29 15:05:36,676] {standard_task_runner.py:79} INFO - Running: ['airflow', 'tasks', 'run', 'dados_climaticos', 'extrai_dados', 'scheduled__2024-09-30T00:00:00+00:00', '--job-id', '38', '--raw', '--subdir', 'DAGS_FOLDER/dados_climaticos.py', '--cfg-path', '/tmp/tmp3un84wa7', '--error-file', '/tmp/tmpfpm13neq']
[2024-10-29 15:05:36,676] {standard_task_runner.py:80} INFO - Job 38: Subtask extrai_dados
[2024-10-29 15:05:36,700] {task_command.py:370} INFO - Running <TaskInstance: dados_climaticos.extrai_dados scheduled__2024-09-30T00:00:00+00:00 [running]> on host LAPTOP-SNAE0A1O.
[2024-10-29 15:05:36,718] {taskinstance.py:1889} ERROR - Task failed with exception
Traceback (most recent call last):
  File "/root/Documentos/airflow/venv/lib/python3.9/site-packages/airflow/models/taskinstance.py", line 1451, in _run_raw_task
    self._execute_task_with_callbacks(context, test_mode)
  File "/root/Documentos/airflow/venv/lib/python3.9/site-packages/airflow/models/taskinstance.py", line 1555, in _execute_task_with_callbacks
    task_orig = self.render_templates(context=context)
  File "/root/Documentos/airflow/venv/lib/python3.9/site-packages/airflow/models/taskinstance.py", line 2212, in render_templates
    rendered_task = self.task.render_template_fields(context)
  File "/root/Documentos/airflow/venv/lib/python3.9/site-packages/airflow/models/baseoperator.py", line 1185, in render_template_fields
    self._do_render_template_fields(self, self.template_fields, context, jinja_env, set())
  File "/root/Documentos/airflow/venv/lib/python3.9/site-packages/airflow/utils/session.py", line 71, in wrapper
    return func(*args, session=session, **kwargs)
  File "/root/Documentos/airflow/venv/lib/python3.9/site-packages/airflow/models/abstractoperator.py", line 344, in _do_render_template_fields
    rendered_content = self.render_template(
  File "/root/Documentos/airflow/venv/lib/python3.9/site-packages/airflow/models/abstractoperator.py", line 404, in render_template
    return {key: self.render_template(value, context, jinja_env) for key, value in value.items()}
  File "/root/Documentos/airflow/venv/lib/python3.9/site-packages/airflow/models/abstractoperator.py", line 404, in <dictcomp>
    return {key: self.render_template(value, context, jinja_env) for key, value in value.items()}
  File "/root/Documentos/airflow/venv/lib/python3.9/site-packages/airflow/models/abstractoperator.py", line 387, in render_template
    template = jinja_env.from_string(value)
  File "/root/Documentos/airflow/venv/lib/python3.9/site-packages/jinja2/environment.py", line 1092, in from_string
    return cls.from_code(self, self.compile(source), gs, None)
  File "/root/Documentos/airflow/venv/lib/python3.9/site-packages/jinja2/environment.py", line 757, in compile
    self.handle_exception(source=source_hint)
  File "/root/Documentos/airflow/venv/lib/python3.9/site-packages/jinja2/environment.py", line 925, in handle_exception
    raise rewrite_traceback_stack(source=source)
  File "<unknown>", line 1, in template
jinja2.exceptions.TemplateSyntaxError: unexpected char '"' at 29
[2024-10-29 15:05:36,721] {taskinstance.py:1395} INFO - Marking task as FAILED. dag_id=dados_climaticos, task_id=extrai_dados, execution_date=20240930T000000, start_date=20241029T180536, end_date=20241029T180536
[2024-10-29 15:05:36,732] {standard_task_runner.py:92} ERROR - Failed to execute job 38 for task extrai_dados (unexpected char '"' at 29; 118548)
[2024-10-29 15:05:36,769] {local_task_job.py:156} INFO - Task exited with return code 1
[2024-10-29 15:05:36,779] {local_task_job.py:273} INFO - 0 downstream tasks scheduled from follow-on schedule check
[2024-10-29 15:11:01,822] {taskinstance.py:1159} INFO - Dependencies all met for <TaskInstance: dados_climaticos.extrai_dados scheduled__2024-09-30T00:00:00+00:00 [queued]>
[2024-10-29 15:11:01,827] {taskinstance.py:1159} INFO - Dependencies all met for <TaskInstance: dados_climaticos.extrai_dados scheduled__2024-09-30T00:00:00+00:00 [queued]>
[2024-10-29 15:11:01,827] {taskinstance.py:1356} INFO - 
--------------------------------------------------------------------------------
[2024-10-29 15:11:01,827] {taskinstance.py:1357} INFO - Starting attempt 1 of 1
[2024-10-29 15:11:01,827] {taskinstance.py:1358} INFO - 
--------------------------------------------------------------------------------
[2024-10-29 15:11:01,839] {taskinstance.py:1377} INFO - Executing <Task(PythonOperator): extrai_dados> on 2024-09-30 00:00:00+00:00
[2024-10-29 15:11:01,842] {standard_task_runner.py:52} INFO - Started process 121164 to run task
[2024-10-29 15:11:01,844] {standard_task_runner.py:79} INFO - Running: ['airflow', 'tasks', 'run', 'dados_climaticos', 'extrai_dados', 'scheduled__2024-09-30T00:00:00+00:00', '--job-id', '38', '--raw', '--subdir', 'DAGS_FOLDER/dados_climaticos.py', '--cfg-path', '/tmp/tmpq1x5tjwk', '--error-file', '/tmp/tmp_odhit8f']
[2024-10-29 15:11:01,845] {standard_task_runner.py:80} INFO - Job 38: Subtask extrai_dados
[2024-10-29 15:11:01,869] {task_command.py:370} INFO - Running <TaskInstance: dados_climaticos.extrai_dados scheduled__2024-09-30T00:00:00+00:00 [running]> on host LAPTOP-SNAE0A1O.
[2024-10-29 15:11:01,904] {taskinstance.py:1569} INFO - Exporting the following env vars:
AIRFLOW_CTX_DAG_OWNER=airflow
AIRFLOW_CTX_DAG_ID=dados_climaticos
AIRFLOW_CTX_TASK_ID=extrai_dados
AIRFLOW_CTX_EXECUTION_DATE=2024-09-30T00:00:00+00:00
AIRFLOW_CTX_TRY_NUMBER=1
AIRFLOW_CTX_DAG_RUN_ID=scheduled__2024-09-30T00:00:00+00:00
[2024-10-29 15:11:02,720] {taskinstance.py:1889} ERROR - Task failed with exception
Traceback (most recent call last):
  File "/root/Documentos/airflow/venv/lib/python3.9/site-packages/airflow/operators/python.py", line 171, in execute
    return_value = self.execute_callable()
  File "/root/Documentos/airflow/venv/lib/python3.9/site-packages/airflow/operators/python.py", line 189, in execute_callable
    return self.python_callable(*self.op_args, **self.op_kwargs)
  File "/root/Documentos/airflow/dags/dados_climaticos.py", line 27, in extrai_dados
    dados = pd.read_csv(URL)
  File "/root/Documentos/airflow/venv/lib/python3.9/site-packages/pandas/io/parsers/readers.py", line 1026, in read_csv
    return _read(filepath_or_buffer, kwds)
  File "/root/Documentos/airflow/venv/lib/python3.9/site-packages/pandas/io/parsers/readers.py", line 620, in _read
    parser = TextFileReader(filepath_or_buffer, **kwds)
  File "/root/Documentos/airflow/venv/lib/python3.9/site-packages/pandas/io/parsers/readers.py", line 1620, in __init__
    self._engine = self._make_engine(f, self.engine)
  File "/root/Documentos/airflow/venv/lib/python3.9/site-packages/pandas/io/parsers/readers.py", line 1880, in _make_engine
    self.handles = get_handle(
  File "/root/Documentos/airflow/venv/lib/python3.9/site-packages/pandas/io/common.py", line 728, in get_handle
    ioargs = _get_filepath_or_buffer(
  File "/root/Documentos/airflow/venv/lib/python3.9/site-packages/pandas/io/common.py", line 384, in _get_filepath_or_buffer
    with urlopen(req_info) as req:
  File "/root/Documentos/airflow/venv/lib/python3.9/site-packages/pandas/io/common.py", line 289, in urlopen
    return urllib.request.urlopen(*args, **kwargs)
  File "/usr/lib/python3.9/urllib/request.py", line 214, in urlopen
    return opener.open(url, data, timeout)
  File "/usr/lib/python3.9/urllib/request.py", line 523, in open
    response = meth(req, response)
  File "/usr/lib/python3.9/urllib/request.py", line 632, in http_response
    response = self.parent.error(
  File "/usr/lib/python3.9/urllib/request.py", line 561, in error
    return self._call_chain(*args)
  File "/usr/lib/python3.9/urllib/request.py", line 494, in _call_chain
    result = func(*args)
  File "/usr/lib/python3.9/urllib/request.py", line 641, in http_error_default
    raise HTTPError(req.full_url, code, msg, hdrs, fp)
urllib.error.HTTPError: HTTP Error 401: 
[2024-10-29 15:11:02,727] {taskinstance.py:1395} INFO - Marking task as FAILED. dag_id=dados_climaticos, task_id=extrai_dados, execution_date=20240930T000000, start_date=20241029T181101, end_date=20241029T181102
[2024-10-29 15:11:02,737] {standard_task_runner.py:92} ERROR - Failed to execute job 38 for task extrai_dados (HTTP Error 401: ; 121164)
[2024-10-29 15:11:02,779] {local_task_job.py:156} INFO - Task exited with return code 1
[2024-10-29 15:11:02,789] {local_task_job.py:273} INFO - 0 downstream tasks scheduled from follow-on schedule check
[2024-10-29 15:14:27,103] {taskinstance.py:1159} INFO - Dependencies all met for <TaskInstance: dados_climaticos.extrai_dados scheduled__2024-09-30T00:00:00+00:00 [queued]>
[2024-10-29 15:14:27,108] {taskinstance.py:1159} INFO - Dependencies all met for <TaskInstance: dados_climaticos.extrai_dados scheduled__2024-09-30T00:00:00+00:00 [queued]>
[2024-10-29 15:14:27,108] {taskinstance.py:1356} INFO - 
--------------------------------------------------------------------------------
[2024-10-29 15:14:27,108] {taskinstance.py:1357} INFO - Starting attempt 1 of 1
[2024-10-29 15:14:27,108] {taskinstance.py:1358} INFO - 
--------------------------------------------------------------------------------
[2024-10-29 15:14:27,119] {taskinstance.py:1377} INFO - Executing <Task(PythonOperator): extrai_dados> on 2024-09-30 00:00:00+00:00
[2024-10-29 15:14:27,122] {standard_task_runner.py:52} INFO - Started process 122868 to run task
[2024-10-29 15:14:27,124] {standard_task_runner.py:79} INFO - Running: ['airflow', 'tasks', 'run', 'dados_climaticos', 'extrai_dados', 'scheduled__2024-09-30T00:00:00+00:00', '--job-id', '38', '--raw', '--subdir', 'DAGS_FOLDER/dados_climaticos.py', '--cfg-path', '/tmp/tmpr4r4he3i', '--error-file', '/tmp/tmpy068650k']
[2024-10-29 15:14:27,124] {standard_task_runner.py:80} INFO - Job 38: Subtask extrai_dados
[2024-10-29 15:14:27,148] {task_command.py:370} INFO - Running <TaskInstance: dados_climaticos.extrai_dados scheduled__2024-09-30T00:00:00+00:00 [running]> on host LAPTOP-SNAE0A1O.
[2024-10-29 15:14:27,183] {taskinstance.py:1569} INFO - Exporting the following env vars:
AIRFLOW_CTX_DAG_OWNER=airflow
AIRFLOW_CTX_DAG_ID=dados_climaticos
AIRFLOW_CTX_TASK_ID=extrai_dados
AIRFLOW_CTX_EXECUTION_DATE=2024-09-30T00:00:00+00:00
AIRFLOW_CTX_TRY_NUMBER=1
AIRFLOW_CTX_DAG_RUN_ID=scheduled__2024-09-30T00:00:00+00:00
[2024-10-29 15:14:28,014] {python.py:173} INFO - Done. Returned value was: None
[2024-10-29 15:14:28,017] {taskinstance.py:1395} INFO - Marking task as SUCCESS. dag_id=dados_climaticos, task_id=extrai_dados, execution_date=20240930T000000, start_date=20241029T181427, end_date=20241029T181428
[2024-10-29 15:14:28,058] {local_task_job.py:156} INFO - Task exited with return code 0
[2024-10-29 15:14:28,069] {local_task_job.py:273} INFO - 0 downstream tasks scheduled from follow-on schedule check
[2024-10-29 19:04:40,707] {taskinstance.py:1159} INFO - Dependencies all met for <TaskInstance: dados_climaticos.extrai_dados scheduled__2024-09-30T00:00:00+00:00 [queued]>
[2024-10-29 19:04:40,712] {taskinstance.py:1159} INFO - Dependencies all met for <TaskInstance: dados_climaticos.extrai_dados scheduled__2024-09-30T00:00:00+00:00 [queued]>
[2024-10-29 19:04:40,712] {taskinstance.py:1356} INFO - 
--------------------------------------------------------------------------------
[2024-10-29 19:04:40,712] {taskinstance.py:1357} INFO - Starting attempt 1 of 1
[2024-10-29 19:04:40,712] {taskinstance.py:1358} INFO - 
--------------------------------------------------------------------------------
[2024-10-29 19:04:40,725] {taskinstance.py:1377} INFO - Executing <Task(PythonOperator): extrai_dados> on 2024-09-30 00:00:00+00:00
[2024-10-29 19:04:40,728] {standard_task_runner.py:52} INFO - Started process 54240 to run task
[2024-10-29 19:04:40,729] {standard_task_runner.py:79} INFO - Running: ['airflow', 'tasks', 'run', 'dados_climaticos', 'extrai_dados', 'scheduled__2024-09-30T00:00:00+00:00', '--job-id', '54', '--raw', '--subdir', 'DAGS_FOLDER/dados_climaticos.py', '--cfg-path', '/tmp/tmpgs9kc0hq', '--error-file', '/tmp/tmpfy1_z7yb']
[2024-10-29 19:04:40,730] {standard_task_runner.py:80} INFO - Job 54: Subtask extrai_dados
[2024-10-29 19:04:40,754] {task_command.py:370} INFO - Running <TaskInstance: dados_climaticos.extrai_dados scheduled__2024-09-30T00:00:00+00:00 [running]> on host LAPTOP-SNAE0A1O.
[2024-10-29 19:04:40,791] {taskinstance.py:1569} INFO - Exporting the following env vars:
AIRFLOW_CTX_DAG_OWNER=airflow
AIRFLOW_CTX_DAG_ID=dados_climaticos
AIRFLOW_CTX_TASK_ID=extrai_dados
AIRFLOW_CTX_EXECUTION_DATE=2024-09-30T00:00:00+00:00
AIRFLOW_CTX_TRY_NUMBER=1
AIRFLOW_CTX_DAG_RUN_ID=scheduled__2024-09-30T00:00:00+00:00
[2024-10-29 19:04:41,777] {python.py:173} INFO - Done. Returned value was: None
[2024-10-29 19:04:41,781] {taskinstance.py:1395} INFO - Marking task as SUCCESS. dag_id=dados_climaticos, task_id=extrai_dados, execution_date=20240930T000000, start_date=20241029T220440, end_date=20241029T220441
[2024-10-29 19:04:41,828] {local_task_job.py:156} INFO - Task exited with return code 0
[2024-10-29 19:04:41,838] {local_task_job.py:273} INFO - 0 downstream tasks scheduled from follow-on schedule check
